Workbook

Sheet 설정 Settings
A1: 설정 Settings — 노란 칸만 고치세요 (edit the yellow cells only)
A2: 노란 칸 = 입력 · 회색 칸 = 자동 계산 또는 config에서 온 값 · "가정"과 "추정"은 근거 자료가 없는 값입니다 (decision memo §5.1). 모든 시장 가격은 검색 요약(snippet)이므로 직접 확인하세요. 세무·법률 자문이 아닙니다.
A3: 항목 | B3: Item | C3: 값 Value | D3: 단위 | E3: 근거·상태 Basis / status | F3: 출처 Source
A4: 브랜드·연락처 Brand & contact — 이메일·문자마다 이름, 우편 주소, 연락처, 수신거부 문구가 필요합니다 (CASL, F11–F13)
A5: 브랜드 (영문) | B5: Brand (EN) | C5: Neighbourhood Home Care | E5: {BRAND}. config/business.ts 기본값 (NEXT_PUBLIC_BRAND_EN). 인보이스에 나옵니다.
A6: 브랜드 (한글) | B6: Brand (KO) | C6: 우리동네 홈케어 | E6: {BRAND}. config/business.ts 기본값 (NEXT_PUBLIC_BRAND_KO). 상호 등록 필요 여부는 확인 필요 (memo §6).
A7: 우편 주소 | B7: Mailing address | C7: {MAILING_ADDRESS} | E7: CASL 필수: "the mailing address" (SOR/2012-36 s.2(1)(d), F13). 사서함(PO box)도 되는지는 규정에 없음 — 확인 필요. | F7: https://github.com/justicecanada/laws-lois-xml/blob/main/eng/regulations/SOR-2012-36.xml
A8: 전화 | B8: Phone | C8: {PHONE} | E8: {PHONE}
A9: 이메일 | B9: Email | C9: {EMAIL} | E9: {EMAIL}
A10: 웹사이트 | B10: Website | C10: {WEBSITE} | E10: {WEBSITE}
A11: e-Transfer 받을 이메일 | B11: e-Transfer email | C11: ='설정 Settings'!$C$9 | E11: 기본값은 위 이메일. 다른 주소로 받으면 직접 입력하세요.
A12: 카드 결제 받음? | B12: Card accepted? | C12: NO | E12: 카드 결제 서비스를 실제로 쓸 때만 YES. Stripe 캐나다 수수료 2.9% + $0.30 (F37, SECONDARY). | F12: https://github.com/kurtrgoddard/Bilingua-App/blob/b1f427aae94ef32e9f78ad5543dad81c330e7956/economy/research-pricing.md
A13: 도시 (빌드 기준) | B13: City (build) | C13: gta | E13: 가격·세율 기본값의 기준 도시. 바꾸려면 다시 빌드: node scripts/build-crm.mjs --city=ottawa
A14: 계획 시작일 | B14: Plan start (day 1) | C14: 46293 | E14: memo: Mon 2026-09-28
A15: 기준일 | B15: As-of date | C15: =TODAY() | E15: 보통 TODAY(). 날짜를 직접 넣으면 그날 기준으로 지표·킬 기준·DAILY 줄을 다시 계산합니다.
A17: 소비자 계약·CASL Consumer contracts & CASL (F11, F32) — 법률 자문 아님
A18: 방문 계약 취소 가능 기간 | B18: Door-signed cancellation period | C18: 10 | D18: 일 | E18: 온타리오 방문(direct) 계약: 서명한 사본을 받은 날부터 10일 안에 취소 가능 (F32, SNIPPET). 기간 중 작업한 경우의 효과는 조사 안 됨. | F18: https://www.ontario.ca/page/your-rights-when-signing-or-cancelling-contract
A19: 취소 시 환불 기한 | B19: Refund due after cancellation | C19: 15 | D19: 일 | E19: 취소하면 15일 안에 환불 (F32) | F19: https://www.ontario.ca/page/your-rights-when-signing-or-cancelling-contract
A20: 문의 후 묵시적 동의 기간 | B20: Implied consent after an inquiry | C20: 6 | D20: 개월 | E20: CASL s.10(10) (F11). 그 뒤 문자·이메일을 보내려면 다른 동의 근거(예: 명시적 동의)가 필요. | F20: https://github.com/justicecanada/laws-lois-xml/blob/main/eng/acts/E-1.6.xml
A21: 수신거부 처리 기한 | B21: Unsubscribe processing time | C21: 10 | D21: 영업일 | E21: CASL: 수신거부는 10영업일 안에 처리, 수신거부 방법은 60일 동안 유효 (F11) | F21: https://github.com/justicecanada/laws-lois-xml/blob/main/eng/acts/E-1.6.xml
A23: 세금 Tax (F7–F10) — 세무 자문 아님
A24: GST/HST 등록? | B24: HST registered | C24: NO | E24: NO가 기본. 4분기 합계 $30,000 전까지 소규모 사업자 (ETA s.148, F7). 자발적 등록은 1년간 취소 불가 (s.242(2), F8). YES면 인보이스에 세금 줄이 나타납니다. | F24: https://github.com/justicecanada/laws-lois-xml/blob/main/eng/acts/E-15.xml
A25: GST/HST 등록번호 | B25: GST/HST number | E25: 등록한 뒤에만 입력
A26: 세율 | B26: Tax rate | C26: 0.13 | E26: config/business.ts TAX_RULES (gta). 온타리오 HST 13% (ETA s.165, Sched. VIII, F8). | F26: https://github.com/justicecanada/laws-lois-xml/blob/main/eng/acts/E-15.xml
A27: 세금 이름 | B27: Tax label | C27: HST 13% | E27: config/business.ts TAX_RULES
A28: 소규모 사업자 기준 | B28: Small-supplier threshold | C28: 30000 | D28: $ | E28: 4분기 합계 테스트 + 단일 분기 테스트 (ETA s.148, F7) | F28: https://github.com/justicecanada/laws-lois-xml/blob/main/eng/acts/E-15.xml
A29: 4분기 합계 경고선 | B29: Rolling 4-quarter warning | C29: 25000 | D29: $ | E29: memo §10 item 15 (미리 준비하기 위한 경고선)
A30: 단일 분기 경고선 | B30: Single-quarter warning | C30: 20000 | D30: $ | E30: memo §10 item 15
A31: 플랫폼 수입을 과세매출에 포함? | B31: Count platform income in HST test | C31: YES | E31: 플랫폼 수입이 본인 과세 공급인지 확인 안 됨 (memo 5.5). 보수적으로 YES.
A32: CPP 적립률 (자영업) | B32: CPP rate (self-employed) | C32: 0.119 | E32: 9.9% + 2.0% = 11.9% (CPP Act, F9) | F32: https://github.com/justicecanada/laws-lois-xml/blob/main/eng/acts/C-8.xml
A33: CPP 기본 공제 | B33: CPP basic exemption | C33: 3500 | D33: $/년 | E33: F9. 적립 권장액은 보수적으로 이 공제를 무시합니다 (memo 5.4). | F33: https://github.com/justicecanada/laws-lois-xml/blob/main/eng/acts/C-8.xml
A34: 카드 수수료율 | B34: Card fee % | C34: 0.029 | E34: Stripe 캐나다 (F37, SECONDARY) | F34: https://github.com/kurtrgoddard/Bilingua-App/blob/b1f427aae94ef32e9f78ad5543dad81c330e7956/economy/research-pricing.md
A35: 카드 건당 수수료 | B35: Card fee per charge | C35: 0.3 | D35: $ | E35: Stripe 캐나다 (F37, SECONDARY) | F35: https://github.com/kurtrgoddard/Bilingua-App/blob/b1f427aae94ef32e9f78ad5543dad81c330e7956/economy/research-pricing.md
A36: e-Transfer 분할 안내 기준 | B36: Split e-Transfer above | C36: 2000 | D36: $ | E36: 은행별 한도 보통 $2,000–3,000 (F36, SECONDARY/사례). 넘으면 나눠 받기. | F36: https://github.com/nifabulous/Relay/blob/885bdf20a690d77dd2b93e46a52a597382039c6e/app/data/payment_schemes.py
A38: EI 고용보험 (memo 5.4, F1–F6) — 모든 계산은 추정. 판단은 Service Canada가 합니다
A39: EI 자격? | B39: EI eligible? | C39: UNKNOWN | E39: 보험가능 근로 420–700시간 필요. 비행(misconduct)이나 정당한 이유 없는 자진 퇴사는 자격 없음 (EI Act s.7(2), s.30(1), F6). 본인이 확인. NO면 EI 계산이 꺼집니다. | F39: https://github.com/justicecanada/laws-lois-xml/blob/main/eng/acts/E-5.6.xml
A40: EI 신청 마감 | B40: EI filing deadline | C40: 46305 | E40: Pilot 24: 2026-10-10까지 시작하는 수급 기간 (SOR-96-332 ss.77.996–77.999, F1). 연장 여부 찾지 못함. | F40: https://github.com/justicecanada/laws-lois-xml/blob/main/eng/regulations/SOR-96-332.xml
A41: EI 시작 주 (일요일) | B41: Benefit period start (Sunday) | C41: 46299 | E41: 10/10까지 신청하면 10/4 시작 (EI Act s.10(1), F2). 실제 날짜로 바꾸세요. | F41: https://github.com/justicecanada/laws-lois-xml/blob/main/eng/acts/E-5.6.xml
A42: 주간 EI 수령액 B | B42: Weekly benefit B | C42: 729 | D42: $/주 | E42: 예시 = 2026 최대치 (68,900 ÷ 52 × 55% = 728.75, F5 SECONDARY). 본인 실제 금액으로 바꾸세요. | F42: https://github.com/Artzp/RetireOps/blob/main/docs/source-of-truth/19-benefits-tax-credits-2026.md
A43: 주간 보험가능소득 | B43: Weekly insurable earnings | C43: 1325 | D43: $/주 | E43: 예시 = 최대 보험가능소득 68,900 ÷ 52 ≈ 1,325 (F5). 본인 금액으로 바꾸세요. | F43: https://github.com/Artzp/RetireOps/blob/main/docs/source-of-truth/19-benefits-tax-credits-2026.md
...

Sheet 문 두드리기 Doors
A1: 날짜 Date | B1: 거리 Street | C1: 집 번호 House # | D1: 시도 # Attempt # | E1: 결과 코드 Outcome | F1: 메모 Notes | G1: 클러스터 Cluster # | I1: 코드 | J1: 뜻 | K1: 할 일
A2: 46295 | B2: EXAMPLE St | C2: 101 | D2: 1 | E2: NA | F2: 예시 행 — 계산에서 제외됨 / EXAMPLE row, not counted | G2: 1 | I2: NA | J2: 부재 No answer | K2: 문고리 광고지를 두고 나중에 다시 (시도 # +1)
I3: NI | J3: 관심 없음 Not interested | K3: 끝. 다시 두드리지 않기
I4: Q | J4: 견적 요청 Quote requested | K4: 견적 시트에 한 줄 (출처 DOOR)
I5: B | J5: 바로 예약 Booked | K5: 견적 시트에 WON + 방문 계약 Y (10일 취소권 안내, F32)
I6: CB | J6: 다시 연락 Call back | K6: 후속 시트에 한 줄
I7: NS | J7: 방문판매 금지 표시 No soliciting | K7: 두드리지 않음. 시도 수에서 빠짐

Sheet 견적 Quotes
A1: 견적 ID Quote ID | B1: 요청일 Request date | C1: 출처 Source | D1: 고객 이름 Customer | E1: 주소 Address | F1: 연락처 Phone / email | G1: 서비스 Service | H1: 견적 금액 (세전) Quote $ (pre-tax) | I1: 상태 Status | J1: 계약일 Won date | K1: 작업 예정일 Scheduled | L1: 방문 계약? Door-signed (Y/N) | M1: 마케팅 수신 동의 Marketing opt-in (Y/N) | N1: 메모 Notes | O1: 취소 가능 기한 (추정) Cancel-by (est.) | P1: 예상 순이익 Est. net | Q1: 후속 알림 Follow-up
A2: EX-Q1 | B2: 46295 | C2: DOOR | D2: EXAMPLE Customer A | E2: 103 EXAMPLE St | F2: 555-0100 | G2: CL-DEEP | H2: 270 | I2: WON | J2: 46297 | K2: 46309 | L2: Y | M2: N | N2: 예시 행 — 계산에서 제외됨 / EXAMPLE row, not counted | O2: (자동) | P2: (자동) | Q2: (자동)
O3: =IF(AND($L3="Y",$J3<>""),$J3+'설정 Settings'!$C$18,"") | P3: =IF($H3="","",$H3-ROUND(IFERROR($H3*VLOOKUP($G3,'설정 Settings'!$A$122:$F$130,4,0)+VLOOKUP($G3,'설정 Settings'!$A$122:$F$130,5,0),0),2)) | Q3: =IF(AND($I3="OPEN",$B3<>""),IF('설정 Settings'!$C$15-$B3>='설정 Settings'!$C$62,"후속 연락 필요",""),"")
O4: =IF(AND($L4="Y",$J4<>""),$J4+'설정 Settings'!$C$18,"") | P4: =IF($H4="","",$H4-ROUND(IFERROR($H4*VLOOKUP($G4,'설정 Settings'!$A$122:$F$130,4,0)+VLOOKUP($G4,'설정 Settings'!$A$122:$F$130,5,0),0),2)) | Q4: =IF(AND($I4="OPEN",$B4<>""),IF('설정 Settings'!$C$15-$B4>='설정 Settings'!$C$62,"후속 연락 필요",""),"")
O5: =IF(AND($L5="Y",$J5<>""),$J5+'설정 Settings'!$C$18,"") | P5: =IF($H5="","",$H5-ROUND(IFERROR($H5*VLOOKUP($G5,'설정 Settings'!$A$122:$F$130,4,0)+VLOOKUP($G5,'설정 Settings'!$A$122:$F$130,5,0),0),2)) | Q5: =IF(AND($I5="OPEN",$B5<>""),IF('설정 Settings'!$C$15-$B5>='설정 Settings'!$C$62,"후속 연락 필요",""),"")
O6: =IF(AND($L6="Y",$J6<>""),$J6+'설정 Settings'!$C$18,"") | P6: =IF($H6="","",$H6-ROUND(IFERROR($H6*VLOOKUP($G6,'설정 Settings'!$A$122:$F$130,4,0)+VLOOKUP($G6,'설정 Settings'!$A$122:$F$130,5,0),0),2)) | Q6: =IF(AND($I6="OPEN",$B6<>""),IF('설정 Settings'!$C$15-$B6>='설정 Settings'!$C$62,"후속 연락 필요",""),"")
O7: =IF(AND($L7="Y",$J7<>""),$J7+'설정 Settings'!$C$18,"") | P7: =IF($H7="","",$H7-ROUND(IFERROR($H7*VLOOKUP($G7,'설정 Settings'!$A$122:$F$130,4,0)+VLOOKUP($G7,'설정 Settings'!$A$122:$F$130,5,0),0),2)) | Q7: =IF(AND($I7="OPEN",$B7<>""),IF('설정 Settings'!$C$15-$B7>='설정 Settings'!$C$62,"후속 연락 필요",""),"")
O8: =IF(AND($L8="Y",$J8<>""),$J8+'설정 Settings'!$C$18,"") | P8: =IF($H8="","",$H8-ROUND(IFERROR($H8*VLOOKUP($G8,'설정 Settings'!$A$122:$F$130,4,0)+VLOOKUP($G8,'설정 Settings'!$A$122:$F$130,5,0),0),2)) | Q8: =IF(AND($I8="OPEN",$B8<>""),IF('설정 Settings'!$C$15-$B8>='설정 Settings'!$C$62,"후속 연락 필요",""),"")
O9: =IF(AND($L9="Y",$J9<>""),$J9+'설정 Settings'!$C$18,"") | P9: =IF($H9="","",$H9-ROUND(IFERROR($H9*VLOOKUP($G9,'설정 Settings'!$A$122:$F$130,4,0)+VLOOKUP($G9,'설정 Settings'!$A$122:$F$130,5,0),0),2)) | Q9: =IF(AND($I9="OPEN",$B9<>""),IF('설정 Settings'!$C$15-$B9>='설정 Settings'!$C$62,"후속 연락 필요",""),"")
O10: =IF(AND($L10="Y",$J10<>""),$J10+'설정 Settings'!$C$18,"") | P10: =IF($H10="","",$H10-ROUND(IFERROR($H10*VLOOKUP($G10,'설정 Settings'!$A$122:$F$130,4,0)+VLOOKUP($G10,'설정 Settings'!$A$122:$F$130,5,0),0),2)) | Q10: =IF(AND($I10="OPEN",$B10<>""),IF('설정 Settings'!$C$15-$B10>='설정 Settings'!$C$62,"후속 연락 필요",""),"")
O11: =IF(AND($L11="Y",$J11<>""),$J11+'설정 Settings'!$C$18,"") | P11: =IF($H11="","",$H11-ROUND(IFERROR($H11*VLOOKUP($G11,'설정 Settings'!$A$122:$F$130,4,0)+VLOOKUP($G11,'설정 Settings'!$A$122:$F$130,5,0),0),2)) | Q11: =IF(AND($I11="OPEN",$B11<>""),IF('설정 Settings'!$C$15-$B11>='설정 Settings'!$C$62,"후속 연락 필요",""),"")
O12: =IF(AND($L12="Y",$J12<>""),$J12+'설정 Settings'!$C$18,"") | P12: =IF($H12="","",$H12-ROUND(IFERROR($H12*VLOOKUP($G12,'설정 Settings'!$A$122:$F$130,4,0)+VLOOKUP($G12,'설정 Settings'!$A$122:$F$130,5,0),0),2)) | Q12: =IF(AND($I12="OPEN",$B12<>""),IF('설정 Settings'!$C$15-$B12>='설정 Settings'!$C$62,"후속 연락 필요",""),"")
O13: =IF(AND($L13="Y",$J13<>""),$J13+'설정 Settings'!$C$18,"") | P13: =IF($H13="","",$H13-ROUND(IFERROR($H13*VLOOKUP($G13,'설정 Settings'!$A$122:$F$130,4,0)+VLOOKUP($G13,'설정 Settings'!$A$122:$F$130,5,0),0),2)) | Q13: =IF(AND($I13="OPEN",$B13<>""),IF('설정 Settings'!$C$15-$B13>='설정 Settings'!$C$62,"후속 연락 필요",""),"")
O14: =IF(AND($L14="Y",$J14<>""),$J14+'설정 Settings'!$C$18,"") | P14: =IF($H14="","",$H14-ROUND(IFERROR($H14*VLOOKUP($G14,'설정 Settings'!$A$122:$F$130,4,0)+VLOOKUP($G14,'설정 Settings'!$A$122:$F$130,5,0),0),2)) | Q14: =IF(AND($I14="OPEN",$B14<>""),IF('설정 Settings'!$C$15-$B14>='설정 Settings'!$C$62,"후속 연락 필요",""),"")
... O1002: =IF(AND($L1002="Y",$J1002<>""),$J1002+'설정 Settings'!$C$18,"") | P1002: =IF($H1002="","",$H1002-ROUND(IFERROR($H1002*VLOOKUP($G1002,'설정 Settings'!$A$122:$F$130,4,0)+VLOOKUP($G1002,'설정 Settings'!$A$122:$F$130,5,0),0),2)) | Q1002: =IF(AND($I1002="OPEN",$B1002<>""),IF('설정 Settings'!$C$15-$B1002>='설정 Settings'!$C$62,"후속 연락 필요",""),"")

Sheet 작업 Jobs
A1: 작업 ID Job ID | B1: 견적 ID Quote ID | C1: 완료일 Completed date | D1: 고객 이름 Customer | E1: 주소 Address | F1: 서비스 Service | G1: 출처 Source | H1: 금액 (세전) Price $ (pre-tax) | I1: 직접비 (실제) Direct costs $ (actual) | J1: 방문 계약? Door-signed (Y/N) | K1: 메모 Notes | L1: 적용 직접비 Direct cost used | M1: 순이익 Net | N1: 직접비 근거 Cost basis | O1: 입금 합계 Paid | P1: 미수금 Balance due | Q1: 인보이스 번호 Invoice # | R1: 분할 안내 Split note
A2: EX-J1 | B2: EX-Q1 | C2: 46309 | D2: EXAMPLE Customer A | E2: 103 EXAMPLE St | F2: CL-DEEP | G2: DOOR | H2: 270 | J2: Y | K2: 예시 행 — 계산에서 제외됨 / EXAMPLE row, not counted | L2: (자동) | M2: (자동) | N2: (자동) | O2: (자동) | P2: (자동) | Q2: (자동) | R2: (자동)
L3: =IF($C3="","",IF($I3="",ROUND(IFERROR($H3*VLOOKUP($F3,'설정 Settings'!$A$122:$F$130,4,0)+VLOOKUP($F3,'설정 Settings'!$A$122:$F$130,5,0),0),2),$I3)) | M3: =IF($C3="","",$H3-$L3) | N3: =IF($C3="","",IF($I3="","추정 ESTIMATE","실제 ACTUAL")) | O3: =IF($A3="","",SUMIFS('입금 Payments'!$C$3:$C$1002,'입금 Payments'!$B$3:$B$1002,$A3)) | P3: =IF($C3="","",ROUND($H3*(1+IF('설정 Settings'!$C$24="YES",'설정 Settings'!$C$26,0)),2)-N($O3)) | Q3: =IF($A3="","","INV-"&$A3) | R3: =IF($H3="","",IF($H3>'설정 Settings'!$C$36,"$2,000 초과: e-Transfer 나눠 받기 (F36)",""))
L4: =IF($C4="","",IF($I4="",ROUND(IFERROR($H4*VLOOKUP($F4,'설정 Settings'!$A$122:$F$130,4,0)+VLOOKUP($F4,'설정 Settings'!$A$122:$F$130,5,0),0),2),$I4)) | M4: =IF($C4="","",$H4-$L4) | N4: =IF($C4="","",IF($I4="","추정 ESTIMATE","실제 ACTUAL")) | O4: =IF($A4="","",SUMIFS('입금 Payments'!$C$3:$C$1002,'입금 Payments'!$B$3:$B$1002,$A4)) | P4: =IF($C4="","",ROUND($H4*(1+IF('설정 Settings'!$C$24="YES",'설정 Settings'!$C$26,0)),2)-N($O4)) | Q4: =IF($A4="","","INV-"&$A4) | R4: =IF($H4="","",IF($H4>'설정 Settings'!$C$36,"$2,000 초과: e-Transfer 나눠 받기 (F36)",""))
L5: =IF($C5="","",IF($I5="",ROUND(IFERROR($H5*VLOOKUP($F5,'설정 Settings'!$A$122:$F$130,4,0)+VLOOKUP($F5,'설정 Settings'!$A$122:$F$130,5,0),0),2),$I5)) | M5: =IF($C5="","",$H5-$L5) | N5: =IF($C5="","",IF($I5="","추정 ESTIMATE","실제 ACTUAL")) | O5: =IF($A5="","",SUMIFS('입금 Payments'!$C$3:$C$1002,'입금 Payments'!$B$3:$B$1002,$A5)) | P5: =IF($C5="","",ROUND($H5*(1+IF('설정 Settings'!$C$24="YES",'설정 Settings'!$C$26,0)),2)-N($O5)) | Q5: =IF($A5="","","INV-"&$A5) | R5: =IF($H5="","",IF($H5>'설정 Settings'!$C$36,"$2,000 초과: e-Transfer 나눠 받기 (F36)",""))
L6: =IF($C6="","",IF($I6="",ROUND(IFERROR($H6*VLOOKUP($F6,'설정 Settings'!$A$122:$F$130,4,0)+VLOOKUP($F6,'설정 Settings'!$A$122:$F$130,5,0),0),2),$I6)) | M6: =IF($C6="","",$H6-$L6) | N6: =IF($C6="","",IF($I6="","추정 ESTIMATE","실제 ACTUAL")) | O6: =IF($A6="","",SUMIFS('입금 Payments'!$C$3:$C$1002,'입금 Payments'!$B$3:$B$1002,$A6)) | P6: =IF($C6="","",ROUND($H6*(1+IF('설정 Settings'!$C$24="YES",'설정 Settings'!$C$26,0)),2)-N($O6)) | Q6: =IF($A6="","","INV-"&$A6) | R6: =IF($H6="","",IF($H6>'설정 Settings'!$C$36,"$2,000 초과: e-Transfer 나눠 받기 (F36)",""))
L7: =IF($C7="","",IF($I7="",ROUND(IFERROR($H7*VLOOKUP($F7,'설정 Settings'!$A$122:$F$130,4,0)+VLOOKUP($F7,'설정 Settings'!$A$122:$F$130,5,0),0),2),$I7)) | M7: =IF($C7="","",$H7-$L7) | N7: =IF($C7="","",IF($I7="","추정 ESTIMATE","실제 ACTUAL")) | O7: =IF($A7="","",SUMIFS('입금 Payments'!$C$3:$C$1002,'입금 Payments'!$B$3:$B$1002,$A7)) | P7: =IF($C7="","",ROUND($H7*(1+IF('설정 Settings'!$C$24="YES",'설정 Settings'!$C$26,0)),2)-N($O7)) | Q7: =IF($A7="","","INV-"&$A7) | R7: =IF($H7="","",IF($H7>'설정 Settings'!$C$36,"$2,000 초과: e-Transfer 나눠 받기 (F36)",""))
L8: =IF($C8="","",IF($I8="",ROUND(IFERROR($H8*VLOOKUP($F8,'설정 Settings'!$A$122:$F$130,4,0)+VLOOKUP($F8,'설정 Settings'!$A$122:$F$130,5,0),0),2),$I8)) | M8: =IF($C8="","",$H8-$L8) | N8: =IF($C8="","",IF($I8="","추정 ESTIMATE","실제 ACTUAL")) | O8: =IF($A8="","",SUMIFS('입금 Payments'!$C$3:$C$1002,'입금 Payments'!$B$3:$B$1002,$A8)) | P8: =IF($C8="","",ROUND($H8*(1+IF('설정 Settings'!$C$24="YES",'설정 Settings'!$C$26,0)),2)-N($O8)) | Q8: =IF($A8="","","INV-"&$A8) | R8: =IF($H8="","",IF($H8>'설정 Settings'!$C$36,"$2,000 초과: e-Transfer 나눠 받기 (F36)",""))
L9: =IF($C9="","",IF($I9="",ROUND(IFERROR($H9*VLOOKUP($F9,'설정 Settings'!$A$122:$F$130,4,0)+VLOOKUP($F9,'설정 Settings'!$A$122:$F$130,5,0),0),2),$I9)) | M9: =IF($C9="","",$H9-$L9) | N9: =IF($C9="","",IF($I9="","추정 ESTIMATE","실제 ACTUAL")) | O9: =IF($A9="","",SUMIFS('입금 Payments'!$C$3:$C$1002,'입금 Payments'!$B$3:$B$1002,$A9)) | P9: =IF($C9="","",ROUND($H9*(1+IF('설정 Settings'!$C$24="YES",'설정 Settings'!$C$26,0)),2)-N($O9)) | Q9: =IF($A9="","","INV-"&$A9) | R9: =IF($H9="","",IF($H9>'설정 Settings'!$C$36,"$2,000 초과: e-Transfer 나눠 받기 (F36)",""))
L10: =IF($C10="","",IF($I10="",ROUND(IFERROR($H10*VLOOKUP($F10,'설정 Settings'!$A$122:$F$130,4,0)+VLOOKUP($F10,'설정 Settings'!$A$122:$F$130,5,0),0),2),$I10)) | M10: =IF($C10="","",$H10-$L10) | N10: =IF($C10="","",IF($I10="","추정 ESTIMATE","실제 ACTUAL")) | O10: =IF($A10="","",SUMIFS('입금 Payments'!$C$3:$C$1002,'입금 Payments'!$B$3:$B$1002,$A10)) | P10: =IF($C10="","",ROUND($H10*(1+IF('설정 Settings'!$C$24="YES",'설정 Settings'!$C$26,0)),2)-N($O10)) | Q10: =IF($A10="","","INV-"&$A10) | R10: =IF($H10="","",IF($H10>'설정 Settings'!$C$36,"$2,000 초과: e-Transfer 나눠 받기 (F36)",""))
L11: =IF($C11="","",IF($I11="",ROUND(IFERROR($H11*VLOOKUP($F11,'설정 Settings'!$A$122:$F$130,4,0)+VLOOKUP($F11,'설정 Settings'!$A$122:$F$130,5,0),0),2),$I11)) | M11: =IF($C11="","",$H11-$L11) | N11: =IF($C11="","",IF($I11="","추정 ESTIMATE","실제 ACTUAL")) | O11: =IF($A11="","",SUMIFS('입금 Payments'!$C$3:$C$1002,'입금 Payments'!$B$3:$B$1002,$A11)) | P11: =IF($C11="","",ROUND($H11*(1+IF('설정 Settings'!$C$24="YES",'설정 Settings'!$C$26,0)),2)-N($O11)) | Q11: =IF($A11="","","INV-"&$A11) | R11: =IF($H11="","",IF($H11>'설정 Settings'!$C$36,"$2,000 초과: e-Transfer 나눠 받기 (F36)",""))
L12: =IF($C12="","",IF($I12="",ROUND(IFERROR($H12*VLOOKUP($F12,'설정 Settings'!$A$122:$F$130,4,0)+VLOOKUP($F12,'설정 Settings'!$A$122:$F$130,5,0),0),2),$I12)) | M12: =IF($C12="","",$H12-$L12) | N12: =IF($C12="","",IF($I12="","추정 ESTIMATE","실제 ACTUAL")) | O12: =IF($A12="","",SUMIFS('입금 Payments'!$C$3:$C$1002,'입금 Payments'!$B$3:$B$1002,$A12)) | P12: =IF($C12="","",ROUND($H12*(1+IF('설정 Settings'!$C$24="YES",'설정 Settings'!$C$26,0)),2)-N($O12)) | Q12: =IF($A12="","","INV-"&$A12) | R12: =IF($H12="","",IF($H12>'설정 Settings'!$C$36,"$2,000 초과: e-Transfer 나눠 받기 (F36)",""))
L13: =IF($C13="","",IF($I13="",ROUND(IFERROR($H13*VLOOKUP($F13,'설정 Settings'!$A$122:$F$130,4,0)+VLOOKUP($F13,'설정 Settings'!$A$122:$F$130,5,0),0),2),$I13)) | M13: =IF($C13="","",$H13-$L13) | N13: =IF($C13="","",IF($I13="","추정 ESTIMATE","실제 ACTUAL")) | O13: =IF($A13="","",SUMIFS('입금 Payments'!$C$3:$C$1002,'입금 Payments'!$B$3:$B$1002,$A13)) | P13: =IF($C13="","",ROUND($H13*(1+IF('설정 Settings'!$C$24="YES",'설정 Settings'!$C$26,0)),2)-N($O13)) | Q13: =IF($A13="","","INV-"&$A13) | R13: =IF($H13="","",IF($H13>'설정 Settings'!$C$36,"$2,000 초과: e-Transfer 나눠 받기 (F36)",""))
L14: =IF($C14="","",IF($I14="",ROUND(IFERROR($H14*VLOOKUP($F14,'설정 Settings'!$A$122:$F$130,4,0)+VLOOKUP($F14,'설정 Settings'!$A$122:$F$130,5,0),0),2),$I14)) | M14: =IF($C14="","",$H14-$L14) | N14: =IF($C14="","",IF($I14="","추정 ESTIMATE","실제 ACTUAL")) | O14: =IF($A14="","",SUMIFS('입금 Payments'!$C$3:$C$1002,'입금 Payments'!$B$3:$B$1002,$A14)) | P14: =IF($C14="","",ROUND($H14*(1+IF('설정 Settings'!$C$24="YES",'설정 Settings'!$C$26,0)),2)-N($O14)) | Q14: =IF($A14="","","INV-"&$A14) | R14: =IF($H14="","",IF($H14>'설정 Settings'!$C$36,"$2,000 초과: e-Transfer 나눠 받기 (F36)",""))
... L1002: =IF($C1002="","",IF($I1002="",ROUND(IFERROR($H1002*VLOOKUP($F1002,'설정 Settings'!$A$122:$F$130,4,0)+VLOOKUP($F1002,'설정 Settings'!$A$122:$F$130,5,0),0),2),$I1002)) | M1002: =IF($C1002="","",$H1002-$L1002) | N1002: =IF($C1002="","",IF($I1002="","추정 ESTIMATE","실제 ACTUAL")) | O1002: =IF($A1002="","",SUMIFS('입금 Payments'!$C$3:$C$1002,'입금 Payments'!$B$3:$B$1002,$A1002)) | P1002: =IF($C1002="","",ROUND($H1002*(1+IF('설정 Settings'!$C$24="YES",'설정 Settings'!$C$26,0)),2)-N($O1002)) | Q1002: =IF($A1002="","","INV-"&$A1002) | R1002: =IF($H1002="","",IF($H1002>'설정 Settings'!$C$36,"$2,000 초과: e-Transfer 나눠 받기 (F36)",""))

Sheet 입금 Payments
A1: 입금일 Date | B1: 작업 ID Job ID | C1: 금액 Amount $ | D1: 방법 Method | E1: 참조번호 Reference | F1: 메모 Notes | G1: 고객 (자동) Customer (auto) | H1: 카드 수수료 (추정) Card fee (est.) | I1: 분할 안내 Split note | J1: 작업 잔액 Job balance
A2: 46309 | B2: EX-J1 | C2: 270 | D2: ETRANSFER | E2: EXAMPLE-REF-001 | F2: 예시 행 — 계산에서 제외됨 / EXAMPLE row, not counted | G2: (자동) | H2: (자동) | I2: (자동) | J2: (자동)
G3: =IF($B3="","",IFERROR(INDEX('작업 Jobs'!$D$3:$D$1002,MATCH($B3,'작업 Jobs'!$A$3:$A$1002,0)),"작업 ID 없음")) | H3: =IF($C3="","",IF($D3="CARD",ROUND($C3*'설정 Settings'!$C$34+'설정 Settings'!$C$35,2),0)) | I3: =IF($C3="","",IF($C3>'설정 Settings'!$C$36,"$2,000 초과: 은행 한도 확인, 나눠 받기 (F36)","")) | J3: =IF($B3="","",IFERROR(INDEX('작업 Jobs'!$P$3:$P$1002,MATCH($B3,'작업 Jobs'!$A$3:$A$1002,0)),""))
G4: =IF($B4="","",IFERROR(INDEX('작업 Jobs'!$D$3:$D$1002,MATCH($B4,'작업 Jobs'!$A$3:$A$1002,0)),"작업 ID 없음")) | H4: =IF($C4="","",IF($D4="CARD",ROUND($C4*'설정 Settings'!$C$34+'설정 Settings'!$C$35,2),0)) | I4: =IF($C4="","",IF($C4>'설정 Settings'!$C$36,"$2,000 초과: 은행 한도 확인, 나눠 받기 (F36)","")) | J4: =IF($B4="","",IFERROR(INDEX('작업 Jobs'!$P$3:$P$1002,MATCH($B4,'작업 Jobs'!$A$3:$A$1002,0)),""))
G5: =IF($B5="","",IFERROR(INDEX('작업 Jobs'!$D$3:$D$1002,MATCH($B5,'작업 Jobs'!$A$3:$A$1002,0)),"작업 ID 없음")) | H5: =IF($C5="","",IF($D5="CARD",ROUND($C5*'설정 Settings'!$C$34+'설정 Settings'!$C$35,2),0)) | I5: =IF($C5="","",IF($C5>'설정 Settings'!$C$36,"$2,000 초과: 은행 한도 확인, 나눠 받기 (F36)","")) | J5: =IF($B5="","",IFERROR(INDEX('작업 Jobs'!$P$3:$P$1002,MATCH($B5,'작업 Jobs'!$A$3:$A$1002,0)),""))
G6: =IF($B6="","",IFERROR(INDEX('작업 Jobs'!$D$3:$D$1002,MATCH($B6,'작업 Jobs'!$A$3:$A$1002,0)),"작업 ID 없음")) | H6: =IF($C6="","",IF($D6="CARD",ROUND($C6*'설정 Settings'!$C$34+'설정 Settings'!$C$35,2),0)) | I6: =IF($C6="","",IF($C6>'설정 Settings'!$C$36,"$2,000 초과: 은행 한도 확인, 나눠 받기 (F36)","")) | J6: =IF($B6="","",IFERROR(INDEX('작업 Jobs'!$P$3:$P$1002,MATCH($B6,'작업 Jobs'!$A$3:$A$1002,0)),""))
G7: =IF($B7="","",IFERROR(INDEX('작업 Jobs'!$D$3:$D$1002,MATCH($B7,'작업 Jobs'!$A$3:$A$1002,0)),"작업 ID 없음")) | H7: =IF($C7="","",IF($D7="CARD",ROUND($C7*'설정 Settings'!$C$34+'설정 Settings'!$C$35,2),0)) | I7: =IF($C7="","",IF($C7>'설정 Settings'!$C$36,"$2,000 초과: 은행 한도 확인, 나눠 받기 (F36)","")) | J7: =IF($B7="","",IFERROR(INDEX('작업 Jobs'!$P$3:$P$1002,MATCH($B7,'작업 Jobs'!$A$3:$A$1002,0)),""))
G8: =IF($B8="","",IFERROR(INDEX('작업 Jobs'!$D$3:$D$1002,MATCH($B8,'작업 Jobs'!$A$3:$A$1002,0)),"작업 ID 없음")) | H8: =IF($C8="","",IF($D8="CARD",ROUND($C8*'설정 Settings'!$C$34+'설정 Settings'!$C$35,2),0)) | I8: =IF($C8="","",IF($C8>'설정 Settings'!$C$36,"$2,000 초과: 은행 한도 확인, 나눠 받기 (F36)","")) | J8: =IF($B8="","",IFERROR(INDEX('작업 Jobs'!$P$3:$P$1002,MATCH($B8,'작업 Jobs'!$A$3:$A$1002,0)),""))
G9: =IF($B9="","",IFERROR(INDEX('작업 Jobs'!$D$3:$D$1002,MATCH($B9,'작업 Jobs'!$A$3:$A$1002,0)),"작업 ID 없음")) | H9: =IF($C9="","",IF($D9="CARD",ROUND($C9*'설정 Settings'!$C$34+'설정 Settings'!$C$35,2),0)) | I9: =IF($C9="","",IF($C9>'설정 Settings'!$C$36,"$2,000 초과: 은행 한도 확인, 나눠 받기 (F36)","")) | J9: =IF($B9="","",IFERROR(INDEX('작업 Jobs'!$P$3:$P$1002,MATCH($B9,'작업 Jobs'!$A$3:$A$1002,0)),""))
G10: =IF($B10="","",IFERROR(INDEX('작업 Jobs'!$D$3:$D$1002,MATCH($B10,'작업 Jobs'!$A$3:$A$1002,0)),"작업 ID 없음")) | H10: =IF($C10="","",IF($D10="CARD",ROUND($C10*'설정 Settings'!$C$34+'설정 Settings'!$C$35,2),0)) | I10: =IF($C10="","",IF($C10>'설정 Settings'!$C$36,"$2,000 초과: 은행 한도 확인, 나눠 받기 (F36)","")) | J10: =IF($B10="","",IFERROR(INDEX('작업 Jobs'!$P$3:$P$1002,MATCH($B10,'작업 Jobs'!$A$3:$A$1002,0)),""))
G11: =IF($B11="","",IFERROR(INDEX('작업 Jobs'!$D$3:$D$1002,MATCH($B11,'작업 Jobs'!$A$3:$A$1002,0)),"작업 ID 없음")) | H11: =IF($C11="","",IF($D11="CARD",ROUND($C11*'설정 Settings'!$C$34+'설정 Settings'!$C$35,2),0)) | I11: =IF($C11="","",IF($C11>'설정 Settings'!$C$36,"$2,000 초과: 은행 한도 확인, 나눠 받기 (F36)","")) | J11: =IF($B11="","",IFERROR(INDEX('작업 Jobs'!$P$3:$P$1002,MATCH($B11,'작업 Jobs'!$A$3:$A$1002,0)),""))
G12: =IF($B12="","",IFERROR(INDEX('작업 Jobs'!$D$3:$D$1002,MATCH($B12,'작업 Jobs'!$A$3:$A$1002,0)),"작업 ID 없음")) | H12: =IF($C12="","",IF($D12="CARD",ROUND($C12*'설정 Settings'!$C$34+'설정 Settings'!$C$35,2),0)) | I12: =IF($C12="","",IF($C12>'설정 Settings'!$C$36,"$2,000 초과: 은행 한도 확인, 나눠 받기 (F36)","")) | J12: =IF($B12="","",IFERROR(INDEX('작업 Jobs'!$P$3:$P$1002,MATCH($B12,'작업 Jobs'!$A$3:$A$1002,0)),""))
G13: =IF($B13="","",IFERROR(INDEX('작업 Jobs'!$D$3:$D$1002,MATCH($B13,'작업 Jobs'!$A$3:$A$1002,0)),"작업 ID 없음")) | H13: =IF($C13="","",IF($D13="CARD",ROUND($C13*'설정 Settings'!$C$34+'설정 Settings'!$C$35,2),0)) | I13: =IF($C13="","",IF($C13>'설정 Settings'!$C$36,"$2,000 초과: 은행 한도 확인, 나눠 받기 (F36)","")) | J13: =IF($B13="","",IFERROR(INDEX('작업 Jobs'!$P$3:$P$1002,MATCH($B13,'작업 Jobs'!$A$3:$A$1002,0)),""))
G14: =IF($B14="","",IFERROR(INDEX('작업 Jobs'!$D$3:$D$1002,MATCH($B14,'작업 Jobs'!$A$3:$A$1002,0)),"작업 ID 없음")) | H14: =IF($C14="","",IF($D14="CARD",ROUND($C14*'설정 Settings'!$C$34+'설정 Settings'!$C$35,2),0)) | I14: =IF($C14="","",IF($C14>'설정 Settings'!$C$36,"$2,000 초과: 은행 한도 확인, 나눠 받기 (F36)","")) | J14: =IF($B14="","",IFERROR(INDEX('작업 Jobs'!$P$3:$P$1002,MATCH($B14,'작업 Jobs'!$A$3:$A$1002,0)),""))
... G1002: =IF($B1002="","",IFERROR(INDEX('작업 Jobs'!$D$3:$D$1002,MATCH($B1002,'작업 Jobs'!$A$3:$A$1002,0)),"작업 ID 없음")) | H1002: =IF($C1002="","",IF($D1002="CARD",ROUND($C1002*'설정 Settings'!$C$34+'설정 Settings'!$C$35,2),0)) | I1002: =IF($C1002="","",IF($C1002>'설정 Settings'!$C$36,"$2,000 초과: 은행 한도 확인, 나눠 받기 (F36)","")) | J1002: =IF($B1002="","",IFERROR(INDEX('작업 Jobs'!$P$3:$P$1002,MATCH($B1002,'작업 Jobs'!$A$3:$A$1002,0)),""))

Sheet 후속 Follow-ups
A1: 등록일 Created | B1: 고객 Customer | C1: 관련 ID Quote / Job ID | D1: 유형 Type | E1: 채널 Channel | F1: 예정일 Due | G1: 완료? Done (Y/N) | H1: 동의 근거 Consent basis | I1: 수신거부? Unsubscribed (Y/N) | J1: 결과 Result | K1: 메모 Notes | L1: 상태 Status | M1: CASL 확인 CASL check | N1: 문의 동의 만료 Inquiry consent ends
A2: 46296 | B2: EXAMPLE Customer B | C2: EX-Q2 | D2: QUOTE | E2: SMS | F2: 46298 | G2: N | H2: INQUIRY | I2: N | K2: 예시 행 — 계산에서 제외됨 / EXAMPLE row, not counted | L2: (자동) | M2: (자동) | N2: (자동)
L3: =IF($A3="","",IF($G3="Y","완료 DONE",IF($F3="","날짜 없음",IF($F3<'설정 Settings'!$C$15,"지남 OVERDUE",IF($F3='설정 Settings'!$C$15,"오늘 TODAY","예정 OPEN"))))) | M3: =IF($A3="","",IF($I3="Y","수신거부: 문자·이메일 보내지 않기",IF(OR($E3="SMS",$E3="EMAIL"),IF(OR($H3="",$H3="NONE"),"동의 근거 없음: 전화·방문만",IF($H3="INQUIRY",IF(N($N3)=0,"견적 요청일을 못 찾음: 관련 ID에 견적 ID(Q-…)를 넣었는지 확인",IF('설정 Settings'!$C$15>N($N3),"문의 후 6개월 지남: 다른 동의 근거 필요","OK: 이름·주소·연락처·수신거부 문구 넣기")),IF($H3="REFERRAL","소개 후 첫 메시지만 OK: 소개자 이름 + 이름·주소·연락처·수신거부 문구. 두 번째부터는 다른 동의 근거 필요",IF(AND($H3="REPLY",$D3<>"QUOTE",$D3<>"CALLBACK"),"문의에 대한 답장이 아님: EXPRESS 또는 INQUIRY 동의 필요","OK: 이름·주소·연락처·수신거부 문구 넣기")))),""))) | N3: =IF($H3="INQUIRY",IFERROR(EDATE(INDEX('견적 Quotes'!$B$3:$B$1002,MATCH($C3,'견적 Quotes'!$A$3:$A$1002,0)),'설정 Settings'!$C$20),""),"")
L4: =IF($A4="","",IF($G4="Y","완료 DONE",IF($F4="","날짜 없음",IF($F4<'설정 Settings'!$C$15,"지남 OVERDUE",IF($F4='설정 Settings'!$C$15,"오늘 TODAY","예정 OPEN"))))) | M4: =IF($A4="","",IF($I4="Y","수신거부: 문자·이메일 보내지 않기",IF(OR($E4="SMS",$E4="EMAIL"),IF(OR($H4="",$H4="NONE"),"동의 근거 없음: 전화·방문만",IF($H4="INQUIRY",IF(N($N4)=0,"견적 요청일을 못 찾음: 관련 ID에 견적 ID(Q-…)를 넣었는지 확인",IF('설정 Settings'!$C$15>N($N4),"문의 후 6개월 지남: 다른 동의 근거 필요","OK: 이름·주소·연락처·수신거부 문구 넣기")),IF($H4="REFERRAL","소개 후 첫 메시지만 OK: 소개자 이름 + 이름·주소·연락처·수신거부 문구. 두 번째부터는 다른 동의 근거 필요",IF(AND($H4="REPLY",$D4<>"QUOTE",$D4<>"CALLBACK"),"문의에 대한 답장이 아님: EXPRESS 또는 INQUIRY 동의 필요","OK: 이름·주소·연락처·수신거부 문구 넣기")))),""))) | N4: =IF($H4="INQUIRY",IFERROR(EDATE(INDEX('견적 Quotes'!$B$3:$B$1002,MATCH($C4,'견적 Quotes'!$A$3:$A$1002,0)),'설정 Settings'!$C$20),""),"")
L5: =IF($A5="","",IF($G5="Y","완료 DONE",IF($F5="","날짜 없음",IF($F5<'설정 Settings'!$C$15,"지남 OVERDUE",IF($F5='설정 Settings'!$C$15,"오늘 TODAY","예정 OPEN"))))) | M5: =IF($A5="","",IF($I5="Y","수신거부: 문자·이메일 보내지 않기",IF(OR($E5="SMS",$E5="EMAIL"),IF(OR($H5="",$H5="NONE"),"동의 근거 없음: 전화·방문만",IF($H5="INQUIRY",IF(N($N5)=0,"견적 요청일을 못 찾음: 관련 ID에 견적 ID(Q-…)를 넣었는지 확인",IF('설정 Settings'!$C$15>N($N5),"문의 후 6개월 지남: 다른 동의 근거 필요","OK: 이름·주소·연락처·수신거부 문구 넣기")),IF($H5="REFERRAL","소개 후 첫 메시지만 OK: 소개자 이름 + 이름·주소·연락처·수신거부 문구. 두 번째부터는 다른 동의 근거 필요",IF(AND($H5="REPLY",$D5<>"QUOTE",$D5<>"CALLBACK"),"문의에 대한 답장이 아님: EXPRESS 또는 INQUIRY 동의 필요","OK: 이름·주소·연락처·수신거부 문구 넣기")))),""))) | N5: =IF($H5="INQUIRY",IFERROR(EDATE(INDEX('견적 Quotes'!$B$3:$B$1002,MATCH($C5,'견적 Quotes'!$A$3:$A$1002,0)),'설정 Settings'!$C$20),""),"")
L6: =IF($A6="","",IF($G6="Y","완료 DONE",IF($F6="","날짜 없음",IF($F6<'설정 Settings'!$C$15,"지남 OVERDUE",IF($F6='설정 Settings'!$C$15,"오늘 TODAY","예정 OPEN"))))) | M6: =IF($A6="","",IF($I6="Y","수신거부: 문자·이메일 보내지 않기",IF(OR($E6="SMS",$E6="EMAIL"),IF(OR($H6="",$H6="NONE"),"동의 근거 없음: 전화·방문만",IF($H6="INQUIRY",IF(N($N6)=0,"견적 요청일을 못 찾음: 관련 ID에 견적 ID(Q-…)를 넣었는지 확인",IF('설정 Settings'!$C$15>N($N6),"문의 후 6개월 지남: 다른 동의 근거 필요","OK: 이름·주소·연락처·수신거부 문구 넣기")),IF($H6="REFERRAL","소개 후 첫 메시지만 OK: 소개자 이름 + 이름·주소·연락처·수신거부 문구. 두 번째부터는 다른 동의 근거 필요",IF(AND($H6="REPLY",$D6<>"QUOTE",$D6<>"CALLBACK"),"문의에 대한 답장이 아님: EXPRESS 또는 INQUIRY 동의 필요","OK: 이름·주소·연락처·수신거부 문구 넣기")))),""))) | N6: =IF($H6="INQUIRY",IFERROR(EDATE(INDEX('견적 Quotes'!$B$3:$B$1002,MATCH($C6,'견적 Quotes'!$A$3:$A$1002,0)),'설정 Settings'!$C$20),""),"")
L7: =IF($A7="","",IF($G7="Y","완료 DONE",IF($F7="","날짜 없음",IF($F7<'설정 Settings'!$C$15,"지남 OVERDUE",IF($F7='설정 Settings'!$C$15,"오늘 TODAY","예정 OPEN"))))) | M7: =IF($A7="","",IF($I7="Y","수신거부: 문자·이메일 보내지 않기",IF(OR($E7="SMS",$E7="EMAIL"),IF(OR($H7="",$H7="NONE"),"동의 근거 없음: 전화·방문만",IF($H7="INQUIRY",IF(N($N7)=0,"견적 요청일을 못 찾음: 관련 ID에 견적 ID(Q-…)를 넣었는지 확인",IF('설정 Settings'!$C$15>N($N7),"문의 후 6개월 지남: 다른 동의 근거 필요","OK: 이름·주소·연락처·수신거부 문구 넣기")),IF($H7="REFERRAL","소개 후 첫 메시지만 OK: 소개자 이름 + 이름·주소·연락처·수신거부 문구. 두 번째부터는 다른 동의 근거 필요",IF(AND($H7="REPLY",$D7<>"QUOTE",$D7<>"CALLBACK"),"문의에 대한 답장이 아님: EXPRESS 또는 INQUIRY 동의 필요","OK: 이름·주소·연락처·수신거부 문구 넣기")))),""))) | N7: =IF($H7="INQUIRY",IFERROR(EDATE(INDEX('견적 Quotes'!$B$3:$B$1002,MATCH($C7,'견적 Quotes'!$A$3:$A$1002,0)),'설정 Settings'!$C$20),""),"")
L8: =IF($A8="","",IF($G8="Y","완료 DONE",IF($F8="","날짜 없음",IF($F8<'설정 Settings'!$C$15,"지남 OVERDUE",IF($F8='설정 Settings'!$C$15,"오늘 TODAY","예정 OPEN"))))) | M8: =IF($A8="","",IF($I8="Y","수신거부: 문자·이메일 보내지 않기",IF(OR($E8="SMS",$E8="EMAIL"),IF(OR($H8="",$H8="NONE"),"동의 근거 없음: 전화·방문만",IF($H8="INQUIRY",IF(N($N8)=0,"견적 요청일을 못 찾음: 관련 ID에 견적 ID(Q-…)를 넣었는지 확인",IF('설정 Settings'!$C$15>N($N8),"문의 후 6개월 지남: 다른 동의 근거 필요","OK: 이름·주소·연락처·수신거부 문구 넣기")),IF($H8="REFERRAL","소개 후 첫 메시지만 OK: 소개자 이름 + 이름·주소·연락처·수신거부 문구. 두 번째부터는 다른 동의 근거 필요",IF(AND($H8="REPLY",$D8<>"QUOTE",$D8<>"CALLBACK"),"문의에 대한 답장이 아님: EXPRESS 또는 INQUIRY 동의 필요","OK: 이름·주소·연락처·수신거부 문구 넣기")))),""))) | N8: =IF($H8="INQUIRY",IFERROR(EDATE(INDEX('견적 Quotes'!$B$3:$B$1002,MATCH($C8,'견적 Quotes'!$A$3:$A$1002,0)),'설정 Settings'!$C$20),""),"")
L9: =IF($A9="","",IF($G9="Y","완료 DONE",IF($F9="","날짜 없음",IF($F9<'설정 Settings'!$C$15,"지남 OVERDUE",IF($F9='설정 Settings'!$C$15,"오늘 TODAY","예정 OPEN"))))) | M9: =IF($A9="","",IF($I9="Y","수신거부: 문자·이메일 보내지 않기",IF(OR($E9="SMS",$E9="EMAIL"),IF(OR($H9="",$H9="NONE"),"동의 근거 없음: 전화·방문만",IF($H9="INQUIRY",IF(N($N9)=0,"견적 요청일을 못 찾음: 관련 ID에 견적 ID(Q-…)를 넣었는지 확인",IF('설정 Settings'!$C$15>N($N9),"문의 후 6개월 지남: 다른 동의 근거 필요","OK: 이름·주소·연락처·수신거부 문구 넣기")),IF($H9="REFERRAL","소개 후 첫 메시지만 OK: 소개자 이름 + 이름·주소·연락처·수신거부 문구. 두 번째부터는 다른 동의 근거 필요",IF(AND($H9="REPLY",$D9<>"QUOTE",$D9<>"CALLBACK"),"문의에 대한 답장이 아님: EXPRESS 또는 INQUIRY 동의 필요","OK: 이름·주소·연락처·수신거부 문구 넣기")))),""))) | N9: =IF($H9="INQUIRY",IFERROR(EDATE(INDEX('견적 Quotes'!$B$3:$B$1002,MATCH($C9,'견적 Quotes'!$A$3:$A$1002,0)),'설정 Settings'!$C$20),""),"")
L10: =IF($A10="","",IF($G10="Y","완료 DONE",IF($F10="","날짜 없음",IF($F10<'설정 Settings'!$C$15,"지남 OVERDUE",IF($F10='설정 Settings'!$C$15,"오늘 TODAY","예정 OPEN"))))) | M10: =IF($A10="","",IF($I10="Y","수신거부: 문자·이메일 보내지 않기",IF(OR($E10="SMS",$E10="EMAIL"),IF(OR($H10="",$H10="NONE"),"동의 근거 없음: 전화·방문만",IF($H10="INQUIRY",IF(N($N10)=0,"견적 요청일을 못 찾음: 관련 ID에 견적 ID(Q-…)를 넣었는지 확인",IF('설정 Settings'!$C$15>N($N10),"문의 후 6개월 지남: 다른 동의 근거 필요","OK: 이름·주소·연락처·수신거부 문구 넣기")),IF($H10="REFERRAL","소개 후 첫 메시지만 OK: 소개자 이름 + 이름·주소·연락처·수신거부 문구. 두 번째부터는 다른 동의 근거 필요",IF(AND($H10="REPLY",$D10<>"QUOTE",$D10<>"CALLBACK"),"문의에 대한 답장이 아님: EXPRESS 또는 INQUIRY 동의 필요","OK: 이름·주소·연락처·수신거부 문구 넣기")))),""))) | N10: =IF($H10="INQUIRY",IFERROR(EDATE(INDEX('견적 Quotes'!$B$3:$B$1002,MATCH($C10,'견적 Quotes'!$A$3:$A$1002,0)),'설정 Settings'!$C$20),""),"")
L11: =IF($A11="","",IF($G11="Y","완료 DONE",IF($F11="","날짜 없음",IF($F11<'설정 Settings'!$C$15,"지남 OVERDUE",IF($F11='설정 Settings'!$C$15,"오늘 TODAY","예정 OPEN"))))) | M11: =IF($A11="","",IF($I11="Y","수신거부: 문자·이메일 보내지 않기",IF(OR($E11="SMS",$E11="EMAIL"),IF(OR($H11="",$H11="NONE"),"동의 근거 없음: 전화·방문만",IF($H11="INQUIRY",IF(N($N11)=0,"견적 요청일을 못 찾음: 관련 ID에 견적 ID(Q-…)를 넣었는지 확인",IF('설정 Settings'!$C$15>N($N11),"문의 후 6개월 지남: 다른 동의 근거 필요","OK: 이름·주소·연락처·수신거부 문구 넣기")),IF($H11="REFERRAL","소개 후 첫 메시지만 OK: 소개자 이름 + 이름·주소·연락처·수신거부 문구. 두 번째부터는 다른 동의 근거 필요",IF(AND($H11="REPLY",$D11<>"QUOTE",$D11<>"CALLBACK"),"문의에 대한 답장이 아님: EXPRESS 또는 INQUIRY 동의 필요","OK: 이름·주소·연락처·수신거부 문구 넣기")))),""))) | N11: =IF($H11="INQUIRY",IFERROR(EDATE(INDEX('견적 Quotes'!$B$3:$B$1002,MATCH($C11,'견적 Quotes'!$A$3:$A$1002,0)),'설정 Settings'!$C$20),""),"")
L12: =IF($A12="","",IF($G12="Y","완료 DONE",IF($F12="","날짜 없음",IF($F12<'설정 Settings'!$C$15,"지남 OVERDUE",IF($F12='설정 Settings'!$C$15,"오늘 TODAY","예정 OPEN"))))) | M12: =IF($A12="","",IF($I12="Y","수신거부: 문자·이메일 보내지 않기",IF(OR($E12="SMS",$E12="EMAIL"),IF(OR($H12="",$H12="NONE"),"동의 근거 없음: 전화·방문만",IF($H12="INQUIRY",IF(N($N12)=0,"견적 요청일을 못 찾음: 관련 ID에 견적 ID(Q-…)를 넣었는지 확인",IF('설정 Settings'!$C$15>N($N12),"문의 후 6개월 지남: 다른 동의 근거 필요","OK: 이름·주소·연락처·수신거부 문구 넣기")),IF($H12="REFERRAL","소개 후 첫 메시지만 OK: 소개자 이름 + 이름·주소·연락처·수신거부 문구. 두 번째부터는 다른 동의 근거 필요",IF(AND($H12="REPLY",$D12<>"QUOTE",$D12<>"CALLBACK"),"문의에 대한 답장이 아님: EXPRESS 또는 INQUIRY 동의 필요","OK: 이름·주소·연락처·수신거부 문구 넣기")))),""))) | N12: =IF($H12="INQUIRY",IFERROR(EDATE(INDEX('견적 Quotes'!$B$3:$B$1002,MATCH($C12,'견적 Quotes'!$A$3:$A$1002,0)),'설정 Settings'!$C$20),""),"")
L13: =IF($A13="","",IF($G13="Y","완료 DONE",IF($F13="","날짜 없음",IF($F13<'설정 Settings'!$C$15,"지남 OVERDUE",IF($F13='설정 Settings'!$C$15,"오늘 TODAY","예정 OPEN"))))) | M13: =IF($A13="","",IF($I13="Y","수신거부: 문자·이메일 보내지 않기",IF(OR($E13="SMS",$E13="EMAIL"),IF(OR($H13="",$H13="NONE"),"동의 근거 없음: 전화·방문만",IF($H13="INQUIRY",IF(N($N13)=0,"견적 요청일을 못 찾음: 관련 ID에 견적 ID(Q-…)를 넣었는지 확인",IF('설정 Settings'!$C$15>N($N13),"문의 후 6개월 지남: 다른 동의 근거 필요","OK: 이름·주소·연락처·수신거부 문구 넣기")),IF($H13="REFERRAL","소개 후 첫 메시지만 OK: 소개자 이름 + 이름·주소·연락처·수신거부 문구. 두 번째부터는 다른 동의 근거 필요",IF(AND($H13="REPLY",$D13<>"QUOTE",$D13<>"CALLBACK"),"문의에 대한 답장이 아님: EXPRESS 또는 INQUIRY 동의 필요","OK: 이름·주소·연락처·수신거부 문구 넣기")))),""))) | N13: =IF($H13="INQUIRY",IFERROR(EDATE(INDEX('견적 Quotes'!$B$3:$B$1002,MATCH($C13,'견적 Quotes'!$A$3:$A$1002,0)),'설정 Settings'!$C$20),""),"")
L14: =IF($A14="","",IF($G14="Y","완료 DONE",IF($F14="","날짜 없음",IF($F14<'설정 Settings'!$C$15,"지남 OVERDUE",IF($F14='설정 Settings'!$C$15,"오늘 TODAY","예정 OPEN"))))) | M14: =IF($A14="","",IF($I14="Y","수신거부: 문자·이메일 보내지 않기",IF(OR($E14="SMS",$E14="EMAIL"),IF(OR($H14="",$H14="NONE"),"동의 근거 없음: 전화·방문만",IF($H14="INQUIRY",IF(N($N14)=0,"견적 요청일을 못 찾음: 관련 ID에 견적 ID(Q-…)를 넣었는지 확인",IF('설정 Settings'!$C$15>N($N14),"문의 후 6개월 지남: 다른 동의 근거 필요","OK: 이름·주소·연락처·수신거부 문구 넣기")),IF($H14="REFERRAL","소개 후 첫 메시지만 OK: 소개자 이름 + 이름·주소·연락처·수신거부 문구. 두 번째부터는 다른 동의 근거 필요",IF(AND($H14="REPLY",$D14<>"QUOTE",$D14<>"CALLBACK"),"문의에 대한 답장이 아님: EXPRESS 또는 INQUIRY 동의 필요","OK: 이름·주소·연락처·수신거부 문구 넣기")))),""))) | N14: =IF($H14="INQUIRY",IFERROR(EDATE(INDEX('견적 Quotes'!$B$3:$B$1002,MATCH($C14,'견적 Quotes'!$A$3:$A$1002,0)),'설정 Settings'!$C$20),""),"")
... L1002: =IF($A1002="","",IF($G1002="Y","완료 DONE",IF($F1002="","날짜 없음",IF($F1002<'설정 Settings'!$C$15,"지남 OVERDUE",IF($F1002='설정 Settings'!$C$15,"오늘 TODAY","예정 OPEN"))))) | M1002: =IF($A1002="","",IF($I1002="Y","수신거부: 문자·이메일 보내지 않기",IF(OR($E1002="SMS",$E1002="EMAIL"),IF(OR($H1002="",$H1002="NONE"),"동의 근거 없음: 전화·방문만",IF($H1002="INQUIRY",IF(N($N1002)=0,"견적 요청일을 못 찾음: 관련 ID에 견적 ID(Q-…)를 넣었는지 확인",IF('설정 Settings'!$C$15>N($N1002),"문의 후 6개월 지남: 다른 동의 근거 필요","OK: 이름·주소·연락처·수신거부 문구 넣기")),IF($H1002="REFERRAL","소개 후 첫 메시지만 OK: 소개자 이름 + 이름·주소·연락처·수신거부 문구. 두 번째부터는 다른 동의 근거 필요",IF(AND($H1002="REPLY",$D1002<>"QUOTE",$D1002<>"CALLBACK"),"문의에 대한 답장이 아님: EXPRESS 또는 INQUIRY 동의 필요","OK: 이름·주소·연락처·수신거부 문구 넣기")))),""))) | N1002: =IF($H1002="INQUIRY",IFERROR(EDATE(INDEX('견적 Quotes'!$B$3:$B$1002,MATCH($C1002,'견적 Quotes'!$A$3:$A$1002,0)),'설정 Settings'!$C$20),""),"")

Sheet 지표 Dashboard
A1: ="지표 Dashboard — 기준일 "&YEAR('설정 Settings'!$C$15)&"-"&TEXT(MONTH('설정 Settings'!$C$15),"00")&"-"&TEXT(DAY('설정 Settings'!$C$15),"00")
A2: 모든 칸이 자동 계산입니다. 기준일은 설정 시트에서 바꿉니다. 비율·목표는 가정(memo A8–A10)으로 시작해 시도 30회부터 측정값으로 바뀝니다. 모든 결과는 추정이며 소득 보장이 아닙니다.
A4: 1. 문 두드리기 누적 Door funnel (전체 기록)
A5: 총 시도 Attempts | B5: =COUNTIFS('문 두드리기 Doors'!$E$3:$E$10002,"NA")+COUNTIFS('문 두드리기 Doors'!$E$3:$E$10002,"NI")+COUNTIFS('문 두드리기 Doors'!$E$3:$E$10002,"Q")+COUNTIFS('문 두드리기 Doors'!$E$3:$E$10002,"B")+COUNTIFS('문 두드리기 Doors'!$E$3:$E$10002,"CB") | D5: NA+NI+Q+B+CB. 재방문도 1회 (memo §7). NS는 제외.
A6: 응답 Answered | B6: =COUNTIFS('문 두드리기 Doors'!$E$3:$E$10002,"NI")+COUNTIFS('문 두드리기 Doors'!$E$3:$E$10002,"Q")+COUNTIFS('문 두드리기 Doors'!$E$3:$E$10002,"B")+COUNTIFS('문 두드리기 Doors'!$E$3:$E$10002,"CB") | D6: NI+Q+B+CB
A7: 문에서 견적 요청 Quote requests at door | B7: =COUNTIFS('문 두드리기 Doors'!$E$3:$E$10002,"Q")+COUNTIFS('문 두드리기 Doors'!$E$3:$E$10002,"B") | D7: Q+B
A8: 방문판매 금지 표시 NS | B8: =COUNTIFS('문 두드리기 Doors'!$E$3:$E$10002,"NS") | D8: 두드리지 않은 집
A9: 견적 시트: 문 출처 견적 Door quotes | B9: =COUNTIFS('견적 Quotes'!$C$3:$C$1002,"DOOR") | D9: Q·B마다 견적 시트에 한 줄씩 넣어야 맞습니다
A10: 문 출처 계약 Door closes (WON) | B10: =COUNTIFS('견적 Quotes'!$C$3:$C$1002,"DOOR",'견적 Quotes'!$I$3:$I$1002,"WON")
A11: 문 출처 완료 작업 Door jobs completed | B11: =COUNTIFS('작업 Jobs'!$G$3:$G$1002,"DOOR")
A12: 전체 완료 작업 All completed jobs | B12: =COUNT('작업 Jobs'!$C$3:$C$1002)
A14: 2. 전환율 Rates — 사용값 = 시도가 최소 기준 이상이고 측정값이 0보다 크면 측정값, 아니면 가정
A15: 지표 | B15: 측정 Measured | C15: 표본 n | D15: 가정 Assumed | E15: 사용 Used | F15: 설명
A16: 응답률 Answer % | B16: =IFERROR($B$6/$B$5,0) | C16: =$B$5 | D16: ='설정 Settings'!$C$49 | E16: =IF(AND($B$5>='설정 Settings'!$C$52,$B$16>0),$B$16,$D$16) | F16: 응답 ÷ 시도 (A8 가정 35%)
A17: 견적률 Quote % | B17: =IFERROR($B$7/$B$6,0) | C17: =$B$6 | D17: ='설정 Settings'!$C$50 | E17: =IF(AND($B$5>='설정 Settings'!$C$52,$B$17>0),$B$17,$D$17) | F17: 문에서 견적 요청 ÷ 응답 (A9 가정 10%)
A18: 계약률 Close % | B18: =IFERROR($B$10/$B$9,0) | C18: =$B$9 | D18: ='설정 Settings'!$C$51 | E18: =IF(AND($B$5>='설정 Settings'!$C$52,$B$18>0),$B$18,$D$18) | F18: 문 출처 WON ÷ 문 출처 견적 (진행 중 포함 — 보수적). 견적 10건 미만이면 흔들림이 큽니다 (A10 가정 40%)
A19: 문→계약 Door→close % | B19: =IFERROR($B$10/$B$5,0) | C19: =$B$5 | D19: =$D$16*$D$17*$D$18 | E19: =$E$16*$E$17*$E$18 | F19: 사용값 = 응답률 × 견적률 × 계약률 (가정이면 1.4%)
A20: 계약 1건당 문 Doors per close | B20: =IFERROR($B$5/$B$10,0) | C20: =$B$10 | D20: =IFERROR(1/$D$19,0) | E20: =IFERROR(1/$E$19,0) | F20: 가정이면 약 71.4문 (memo 5.1)
A21: 완료 1건당 문 Doors per completed job | B21: =IFERROR($B$5/$B$11,0) | C21: =$B$11 | F21: 문 출처 완료 작업 기준
A22: 측정값 사용 여부 | B22: =IF($B$5>='설정 Settings'!$C$52,"측정값 사용 (시도 "&$B$5&"회)","가정 사용 — 시도 "&$B$5&"/"&'설정 Settings'!$C$52)
A24: 3. 다음 주 문 목표 Next-week door target (memo §7) — 필요 문 수 = 필요 계약 ÷ (응답률 × 견적률 × 계약률)
A25: 시나리오 Scenario | B25: ='설정 Settings'!$C$53 | D25: 설정 시트
A26: 다음 주 필요 계약 수 Closes needed | B26: ='설정 Settings'!$C$55 | D26: 그다음 주 완료 목표 (설정 시트 주별 목표표 또는 직접 입력)
A27: 다음 주 문 목표 Door target next week | B27: =IF($B$26="","설정에서 입력 필요",ROUNDUP(IFERROR($B$26/$E$19,0),0)) | D27: 재방문 포함 시도 수. 광고·B2B에서 계약이 오면 더 적어도 됩니다 (memo §7: 상한값).
A28: 예상 노크 시간 (시간) Door hours | B28: =IFERROR(ROUND($B$27*'설정 Settings'!$C$60/60,1),0) | D28: 가정 A11: 1회 2분. 작업 있는 날은 최대 40문 (memo §7).
A29: 현재 클러스터 Active cluster | B29: ='설정 Settings'!$C$56
A30: 클러스터 가구 수 Homes in cluster | B30: =IFERROR(INDEX('설정 Settings'!$C$57:$C$59,$B$29),0) | D30: 설정 시트
A31: 최종 결과가 난 집 Homes with a final outcome | B31: =COUNTIFS('문 두드리기 Doors'!$E$3:$E$10002,"NI",'문 두드리기 Doors'!$G$3:$G$10002,$B$29)+COUNTIFS('문 두드리기 Doors'!$E$3:$E$10002,"Q",'문 두드리기 Doors'!$G$3:$G$10002,$B$29)+COUNTIFS('문 두드리기 Doors'!$E$3:$E$10002,"B",'문 두드리기 Doors'!$G$3:$G$10002,$B$29)+COUNTIFS('문 두드리기 Doors'!$E$3:$E$10002,"NS",'문 두드리기 Doors'!$G$3:$G$10002,$B$29)+IF($B$29=1,COUNTIFS('문 두드리기 Doors'!$E$3:$E$10002,"NI",'문 두드리기 Doors'!$G$3:$G$10002,"")+COUNTIFS('문 두드리기 Doors'!$E$3:$E$10002,"Q",'문 두드리기 Doors'!$G$3:$G$10002,"")+COUNTIFS('문 두드리기 Doors'!$E$3:$E$10002,"B",'문 두드리기 Doors'!$G$3:$G$10002,"")+COUNTIFS('문 두드리기 Doors'!$E$3:$E$10002,"NS",'문 두드리기 Doors'!$G$3:$G$10002,""),0) | D31: NI+Q+B+NS (클러스터 칸이 비면 1로 계산). NA·CB는 아직 끝나지 않은 집.
A32: 남은 가구 Homes left | B32: =$B$30-$B$31 | D32: 클러스터 가구 수 − 최종 결과가 난 집
A33: 클러스터 #2 필요? Open cluster #2? | B33: =IF(ISNUMBER($B$27),IF($B$32<2*$B$27,"클러스터 #2 열기 — 남은 가구 < 2 × 문 목표","OK — 현재 클러스터 유지"),"-") | D33: memo §7: 남은 가구 < 2 × 필요 문 수이면 클러스터 #2
A35: 4. 수입 Run-rate — 최근 7일 완료 작업의 순이익 (설비·연 보험료 제외, memo §8)
A36: 최근 7일 순이익 Trailing-7-day net | B36: =SUMIFS('작업 Jobs'!$M$3:$M$1002,'작업 Jobs'!$C$3:$C$1002,">="&('설정 Settings'!$C$15-6),'작업 Jobs'!$C$3:$C$1002,"<="&'설정 Settings'!$C$15) | D36: 작업 시트: 완료일이 기준일−6 ~ 기준일인 작업의 순이익 합
A37: 최근 7일 완료 건수 Jobs (7 days) | B37: =COUNTIFS('작업 Jobs'!$C$3:$C$1002,">="&('설정 Settings'!$C$15-6),'작업 Jobs'!$C$3:$C$1002,"<="&'설정 Settings'!$C$15)
A38: 월 환산 Monthly pace (×4.33, 추정) | B38: =$B$36*4.33 | D38: 추정: 한 달 ≈ 4.33주. 소득 보장 아님.
A39: 이번 달 순이익 Month-to-date net | B39: =SUMIFS('작업 Jobs'!$M$3:$M$1002,'작업 Jobs'!$C$3:$C$1002,">="&DATE(YEAR('설정 Settings'!$C$15),MONTH('설정 Settings'!$C$15),1),'작업 Jobs'!$C$3:$C$1002,"<="&'설정 Settings'!$C$15) | D39: 월 고정비(가정 A7)는 빼지 않은 값
A40: 미수금 합계 Unpaid balances | B40: =SUMIF('작업 Jobs'!$P$3:$P$1002,">0") | D40: 작업 시트 미수금 > 0 합계
A41: 진행 중 견적 Open quotes | B41: =COUNTIF('견적 Quotes'!$I$3:$I$1002,"OPEN")
A42: 지난 후속 연락 Overdue follow-ups | B42: =COUNTIF('후속 Follow-ups'!$L$3:$L$1002,"지남 OVERDUE")
A43: EI Path A / B 판단 | B43: ='EI 주간신고'!$R$14 | D43: EI 주간신고 시트 (memo 5.4). 판단은 Service Canada.
A45: 5. 킬 기준 Kill criteria (memo §8) — PASS 통과 · FAIL/ACTION 조치 · PENDING 아직 날짜 전
...

Sheet EI 주간신고
A1: EI 주간신고 — 추정 계산 (최종 판단은 Service Canada)
A2: 순수입 = 총수입 − 운영비 (EI Regs s.35(10)(c)); 수입은 일한 주에 배분 (s.36(6)); 모든 수입 신고, 신고 안 한 수입은 환수 (F4). 사업이 "경미한 정도(minor extent)"를 넘으면 그 주는 EI 없음 (s.30, F3). 총수입은 작업 시트, 운영비는 지출 시트에서 자동으로 옵니다. 법률 자문 아님.
A3: 주 시작 (일) Week start (Sun) | B3: 주 끝 (토) Week end | C3: 총수입 Gross | D3: 운영비 Operating exp. | E3: 순수입 Net = 총수입 − 운영비 | F3: 경로 Path | G3: EI 공제 추정 Est. deduction | H3: EI 수령 추정 Est. EI paid | I3: Path A 합계 EI + 순수입 | J3: CPP 뺀 합계 After CPP | K3: Path B 비교 (EI 없음, CPP 뺀) | L3: 이 주 기준 전환선 Switch line | M3: 신고함? Declared | N3: 신고일 Declared on | O3: 메모 Notes | Q3: 항목 Item | R3: 값 | S3: 근거
A4: 46292 | B4: =$A4+6 | C4: =SUMIFS('작업 Jobs'!$H$3:$H$1002,'작업 Jobs'!$C$3:$C$1002,">="&$A4,'작업 Jobs'!$C$3:$C$1002,"<="&$B4) | D4: =SUMIFS('지출 Expenses'!$D$3:$D$1002,'지출 Expenses'!$A$3:$A$1002,">="&$A4,'지출 Expenses'!$A$3:$A$1002,"<="&$B4) | E4: =$C4-$D4 | F4: =IF(OR('설정 Settings'!$C$39="NO",$A4<'설정 Settings'!$C$41),"-","A") | G4: =IF($E4<=0,0,'설정 Settings'!$C$44*MIN($E4,$R$6)+MAX(0,$E4-$R$6)) | H4: =IF($F4="A",MAX(0,$R$4-$G4),0) | I4: =$H4+$E4 | J4: =$H4+$E4-MAX(0,$E4)*$R$7 | K4: =$E4-MAX(0,$E4)*$R$7 | L4: =IFERROR(($R$4-'설정 Settings'!$C$44*$E4+(1-$R$7)*$E4)/(1-$R$7),"") | Q4: 주간 EI 수령액 B | R4: ='설정 Settings'!$C$42 | S4: 설정 시트 (예시 = 2026 최대 $729, F5)
A5: 46299 | B5: =$A5+6 | C5: =SUMIFS('작업 Jobs'!$H$3:$H$1002,'작업 Jobs'!$C$3:$C$1002,">="&$A5,'작업 Jobs'!$C$3:$C$1002,"<="&$B5) | D5: =SUMIFS('지출 Expenses'!$D$3:$D$1002,'지출 Expenses'!$A$3:$A$1002,">="&$A5,'지출 Expenses'!$A$3:$A$1002,"<="&$B5) | E5: =$C5-$D5 | F5: =IF(OR('설정 Settings'!$C$39="NO",$A5<'설정 Settings'!$C$41),"-","A") | G5: =IF($E5<=0,0,'설정 Settings'!$C$44*MIN($E5,$R$6)+MAX(0,$E5-$R$6)) | H5: =IF($F5="A",MAX(0,$R$4-$G5),0) | I5: =$H5+$E5 | J5: =$H5+$E5-MAX(0,$E5)*$R$7 | K5: =$E5-MAX(0,$E5)*$R$7 | L5: =IFERROR(($R$4-'설정 Settings'!$C$44*$E5+(1-$R$7)*$E5)/(1-$R$7),"") | Q5: 주간 보험가능소득 | R5: ='설정 Settings'!$C$43 | S5: 설정 시트
A6: 46306 | B6: =$A6+6 | C6: =SUMIFS('작업 Jobs'!$H$3:$H$1002,'작업 Jobs'!$C$3:$C$1002,">="&$A6,'작업 Jobs'!$C$3:$C$1002,"<="&$B6) | D6: =SUMIFS('지출 Expenses'!$D$3:$D$1002,'지출 Expenses'!$A$3:$A$1002,">="&$A6,'지출 Expenses'!$A$3:$A$1002,"<="&$B6) | E6: =$C6-$D6 | F6: =IF(OR('설정 Settings'!$C$39="NO",$A6<'설정 Settings'!$C$41),"-","A") | G6: =IF($E6<=0,0,'설정 Settings'!$C$44*MIN($E6,$R$6)+MAX(0,$E6-$R$6)) | H6: =IF($F6="A",MAX(0,$R$4-$G6),0) | I6: =$H6+$E6 | J6: =$H6+$E6-MAX(0,$E6)*$R$7 | K6: =$E6-MAX(0,$E6)*$R$7 | L6: =IFERROR(($R$4-'설정 Settings'!$C$44*$E6+(1-$R$7)*$E6)/(1-$R$7),"") | Q6: 50% 구간 한도 (90%) | R6: ='설정 Settings'!$C$43*'설정 Settings'!$C$45 | S6: F4
A7: 46313 | B7: =$A7+6 | C7: =SUMIFS('작업 Jobs'!$H$3:$H$1002,'작업 Jobs'!$C$3:$C$1002,">="&$A7,'작업 Jobs'!$C$3:$C$1002,"<="&$B7) | D7: =SUMIFS('지출 Expenses'!$D$3:$D$1002,'지출 Expenses'!$A$3:$A$1002,">="&$A7,'지출 Expenses'!$A$3:$A$1002,"<="&$B7) | E7: =$C7-$D7 | F7: =IF(OR('설정 Settings'!$C$39="NO",$A7<'설정 Settings'!$C$41),"-","A") | G7: =IF($E7<=0,0,'설정 Settings'!$C$44*MIN($E7,$R$6)+MAX(0,$E7-$R$6)) | H7: =IF($F7="A",MAX(0,$R$4-$G7),0) | I7: =$H7+$E7 | J7: =$H7+$E7-MAX(0,$E7)*$R$7 | K7: =$E7-MAX(0,$E7)*$R$7 | L7: =IFERROR(($R$4-'설정 Settings'!$C$44*$E7+(1-$R$7)*$E7)/(1-$R$7),"") | Q7: CPP 비율 | R7: ='설정 Settings'!$C$32 | S7: F9
A8: 46320 | B8: =$A8+6 | C8: =SUMIFS('작업 Jobs'!$H$3:$H$1002,'작업 Jobs'!$C$3:$C$1002,">="&$A8,'작업 Jobs'!$C$3:$C$1002,"<="&$B8) | D8: =SUMIFS('지출 Expenses'!$D$3:$D$1002,'지출 Expenses'!$A$3:$A$1002,">="&$A8,'지출 Expenses'!$A$3:$A$1002,"<="&$B8) | E8: =$C8-$D8 | F8: =IF(OR('설정 Settings'!$C$39="NO",$A8<'설정 Settings'!$C$41),"-","A") | G8: =IF($E8<=0,0,'설정 Settings'!$C$44*MIN($E8,$R$6)+MAX(0,$E8-$R$6)) | H8: =IF($F8="A",MAX(0,$R$4-$G8),0) | I8: =$H8+$E8 | J8: =$H8+$E8-MAX(0,$E8)*$R$7 | K8: =$E8-MAX(0,$E8)*$R$7 | L8: =IFERROR(($R$4-'설정 Settings'!$C$44*$E8+(1-$R$7)*$E8)/(1-$R$7),"") | Q8: Path A 계획 순수입 A | R8: ='설정 Settings'!$C$46 | S8: memo 5.4 예시 $400
A9: 46327 | B9: =$A9+6 | C9: =SUMIFS('작업 Jobs'!$H$3:$H$1002,'작업 Jobs'!$C$3:$C$1002,">="&$A9,'작업 Jobs'!$C$3:$C$1002,"<="&$B9) | D9: =SUMIFS('지출 Expenses'!$D$3:$D$1002,'지출 Expenses'!$A$3:$A$1002,">="&$A9,'지출 Expenses'!$A$3:$A$1002,"<="&$B9) | E9: =$C9-$D9 | F9: =IF(OR('설정 Settings'!$C$39="NO",$A9<'설정 Settings'!$C$41),"-","A") | G9: =IF($E9<=0,0,'설정 Settings'!$C$44*MIN($E9,$R$6)+MAX(0,$E9-$R$6)) | H9: =IF($F9="A",MAX(0,$R$4-$G9),0) | I9: =$H9+$E9 | J9: =$H9+$E9-MAX(0,$E9)*$R$7 | K9: =$E9-MAX(0,$E9)*$R$7 | L9: =IFERROR(($R$4-'설정 Settings'!$C$44*$E9+(1-$R$7)*$E9)/(1-$R$7),"") | Q9: Path B 전환선 (주) | R9: =IFERROR(($R$4-'설정 Settings'!$C$44*$R$8+(1-$R$7)*$R$8)/(1-$R$7),0) | S9: memo 5.4: (B − 0.5A + 0.881A) ÷ 0.881. 최대 EI면 약 $1,000
A10: 46334 | B10: =$A10+6 | C10: =SUMIFS('작업 Jobs'!$H$3:$H$1002,'작업 Jobs'!$C$3:$C$1002,">="&$A10,'작업 Jobs'!$C$3:$C$1002,"<="&$B10) | D10: =SUMIFS('지출 Expenses'!$D$3:$D$1002,'지출 Expenses'!$A$3:$A$1002,">="&$A10,'지출 Expenses'!$A$3:$A$1002,"<="&$B10) | E10: =$C10-$D10 | F10: =IF(OR('설정 Settings'!$C$39="NO",$A10<'설정 Settings'!$C$41),"-","A") | G10: =IF($E10<=0,0,'설정 Settings'!$C$44*MIN($E10,$R$6)+MAX(0,$E10-$R$6)) | H10: =IF($F10="A",MAX(0,$R$4-$G10),0) | I10: =$H10+$E10 | J10: =$H10+$E10-MAX(0,$E10)*$R$7 | K10: =$E10-MAX(0,$E10)*$R$7 | L10: =IFERROR(($R$4-'설정 Settings'!$C$44*$E10+(1-$R$7)*$E10)/(1-$R$7),"") | Q10: 공식 적용 확인 | R10: =IF($R$8>$R$6,"A가 90% 한도 초과 — 전환선 재계산 필요","OK") | S10: A가 50% 구간 안에 있어야 공식이 맞습니다
A11: 46341 | B11: =$A11+6 | C11: =SUMIFS('작업 Jobs'!$H$3:$H$1002,'작업 Jobs'!$C$3:$C$1002,">="&$A11,'작업 Jobs'!$C$3:$C$1002,"<="&$B11) | D11: =SUMIFS('지출 Expenses'!$D$3:$D$1002,'지출 Expenses'!$A$3:$A$1002,">="&$A11,'지출 Expenses'!$A$3:$A$1002,"<="&$B11) | E11: =$C11-$D11 | F11: =IF(OR('설정 Settings'!$C$39="NO",$A11<'설정 Settings'!$C$41),"-","A") | G11: =IF($E11<=0,0,'설정 Settings'!$C$44*MIN($E11,$R$6)+MAX(0,$E11-$R$6)) | H11: =IF($F11="A",MAX(0,$R$4-$G11),0) | I11: =$H11+$E11 | J11: =$H11+$E11-MAX(0,$E11)*$R$7 | K11: =$E11-MAX(0,$E11)*$R$7 | L11: =IFERROR(($R$4-'설정 Settings'!$C$44*$E11+(1-$R$7)*$E11)/(1-$R$7),"") | Q11: 지난 2주 완료 순이익 | R11: =SUMIFS('작업 Jobs'!$M$3:$M$1002,'작업 Jobs'!$C$3:$C$1002,">="&('설정 Settings'!$C$15-13),'작업 Jobs'!$C$3:$C$1002,"<="&'설정 Settings'!$C$15) | S11: 작업 시트 (기준일 포함 14일)
A12: 46348 | B12: =$A12+6 | C12: =SUMIFS('작업 Jobs'!$H$3:$H$1002,'작업 Jobs'!$C$3:$C$1002,">="&$A12,'작업 Jobs'!$C$3:$C$1002,"<="&$B12) | D12: =SUMIFS('지출 Expenses'!$D$3:$D$1002,'지출 Expenses'!$A$3:$A$1002,">="&$A12,'지출 Expenses'!$A$3:$A$1002,"<="&$B12) | E12: =$C12-$D12 | F12: =IF(OR('설정 Settings'!$C$39="NO",$A12<'설정 Settings'!$C$41),"-","A") | G12: =IF($E12<=0,0,'설정 Settings'!$C$44*MIN($E12,$R$6)+MAX(0,$E12-$R$6)) | H12: =IF($F12="A",MAX(0,$R$4-$G12),0) | I12: =$H12+$E12 | J12: =$H12+$E12-MAX(0,$E12)*$R$7 | K12: =$E12-MAX(0,$E12)*$R$7 | L12: =IFERROR(($R$4-'설정 Settings'!$C$44*$E12+(1-$R$7)*$E12)/(1-$R$7),"") | Q12: 앞으로 2주 예약 순이익 | R12: =SUMIFS('견적 Quotes'!$P$3:$P$1002,'견적 Quotes'!$I$3:$I$1002,"WON",'견적 Quotes'!$G$3:$G$1002,"<>SNOW",'견적 Quotes'!$K$3:$K$1002,">"&'설정 Settings'!$C$15,'견적 Quotes'!$K$3:$K$1002,"<="&('설정 Settings'!$C$15+14)) | S12: 견적 시트: WON + 예정일이 앞으로 14일 (추정 순이익). 제설 시즌 계약(SNOW)은 제외: 견적 금액이 12–3월에 나눠 버는 시즌 총액이라서입니다. 할부는 작업 시트에 회차마다 한 줄씩(12/1, 1/1, 2/1, 3/1) 넣으면 “지난 2주 완료”에 잡힙니다.
A13: 46355 | B13: =$A13+6 | C13: =SUMIFS('작업 Jobs'!$H$3:$H$1002,'작업 Jobs'!$C$3:$C$1002,">="&$A13,'작업 Jobs'!$C$3:$C$1002,"<="&$B13) | D13: =SUMIFS('지출 Expenses'!$D$3:$D$1002,'지출 Expenses'!$A$3:$A$1002,">="&$A13,'지출 Expenses'!$A$3:$A$1002,"<="&$B13) | E13: =$C13-$D13 | F13: =IF(OR('설정 Settings'!$C$39="NO",$A13<'설정 Settings'!$C$41),"-","A") | G13: =IF($E13<=0,0,'설정 Settings'!$C$44*MIN($E13,$R$6)+MAX(0,$E13-$R$6)) | H13: =IF($F13="A",MAX(0,$R$4-$G13),0) | I13: =$H13+$E13 | J13: =$H13+$E13-MAX(0,$E13)*$R$7 | K13: =$E13-MAX(0,$E13)*$R$7 | L13: =IFERROR(($R$4-'설정 Settings'!$C$44*$E13+(1-$R$7)*$E13)/(1-$R$7),"") | Q13: 주당 평균 (4주) | R13: =IFERROR(($R$11+$R$12)/4,0) | S13: 해석(추정): (지난 2주 완료 + 앞으로 2주 예약) ÷ 4주 (memo 5.4 규칙 3)
A14: 46362 | B14: =$A14+6 | C14: =SUMIFS('작업 Jobs'!$H$3:$H$1002,'작업 Jobs'!$C$3:$C$1002,">="&$A14,'작업 Jobs'!$C$3:$C$1002,"<="&$B14) | D14: =SUMIFS('지출 Expenses'!$D$3:$D$1002,'지출 Expenses'!$A$3:$A$1002,">="&$A14,'지출 Expenses'!$A$3:$A$1002,"<="&$B14) | E14: =$C14-$D14 | F14: =IF(OR('설정 Settings'!$C$39="NO",$A14<'설정 Settings'!$C$41),"-","A") | G14: =IF($E14<=0,0,'설정 Settings'!$C$44*MIN($E14,$R$6)+MAX(0,$E14-$R$6)) | H14: =IF($F14="A",MAX(0,$R$4-$G14),0) | I14: =$H14+$E14 | J14: =$H14+$E14-MAX(0,$E14)*$R$7 | K14: =$E14-MAX(0,$E14)*$R$7 | L14: =IFERROR(($R$4-'설정 Settings'!$C$44*$E14+(1-$R$7)*$E14)/(1-$R$7),"") | Q14: 판단 | R14: =IF('설정 Settings'!$C$39="NO","EI 없음 — Path B (사업 전념)",IF($R$13>=$R$9,"Path B 전환 검토 (주 $"&ROUND($R$9,0)&" 이상)","Path A 유지")) | S14: 10월 기본값은 Path A (memo 5.4). Service Canada에 "minor extent" 여부를 먼저 전화로 물어보세요.
A15: 46369 | B15: =$A15+6 | C15: =SUMIFS('작업 Jobs'!$H$3:$H$1002,'작업 Jobs'!$C$3:$C$1002,">="&$A15,'작업 Jobs'!$C$3:$C$1002,"<="&$B15) | D15: =SUMIFS('지출 Expenses'!$D$3:$D$1002,'지출 Expenses'!$A$3:$A$1002,">="&$A15,'지출 Expenses'!$A$3:$A$1002,"<="&$B15) | E15: =$C15-$D15 | F15: =IF(OR('설정 Settings'!$C$39="NO",$A15<'설정 Settings'!$C$41),"-","A") | G15: =IF($E15<=0,0,'설정 Settings'!$C$44*MIN($E15,$R$6)+MAX(0,$E15-$R$6)) | H15: =IF($F15="A",MAX(0,$R$4-$G15),0) | I15: =$H15+$E15 | J15: =$H15+$E15-MAX(0,$E15)*$R$7 | K15: =$E15-MAX(0,$E15)*$R$7 | L15: =IFERROR(($R$4-'설정 Settings'!$C$44*$E15+(1-$R$7)*$E15)/(1-$R$7),"") | Q15: EI 신청 마감 | R15: ='설정 Settings'!$C$40 | S15: F1 (Pilot 24)
A16: 46376 | B16: =$A16+6 | C16: =SUMIFS('작업 Jobs'!$H$3:$H$1002,'작업 Jobs'!$C$3:$C$1002,">="&$A16,'작업 Jobs'!$C$3:$C$1002,"<="&$B16) | D16: =SUMIFS('지출 Expenses'!$D$3:$D$1002,'지출 Expenses'!$A$3:$A$1002,">="&$A16,'지출 Expenses'!$A$3:$A$1002,"<="&$B16) | E16: =$C16-$D16 | F16: =IF(OR('설정 Settings'!$C$39="NO",$A16<'설정 Settings'!$C$41),"-","A") | G16: =IF($E16<=0,0,'설정 Settings'!$C$44*MIN($E16,$R$6)+MAX(0,$E16-$R$6)) | H16: =IF($F16="A",MAX(0,$R$4-$G16),0) | I16: =$H16+$E16 | J16: =$H16+$E16-MAX(0,$E16)*$R$7 | K16: =$E16-MAX(0,$E16)*$R$7 | L16: =IFERROR(($R$4-'설정 Settings'!$C$44*$E16+(1-$R$7)*$E16)/(1-$R$7),"") | Q16: EI 자격 | R16: ='설정 Settings'!$C$39 | S16: 설정 시트
A17: 46383 | B17: =$A17+6 | C17: =SUMIFS('작업 Jobs'!$H$3:$H$1002,'작업 Jobs'!$C$3:$C$1002,">="&$A17,'작업 Jobs'!$C$3:$C$1002,"<="&$B17) | D17: =SUMIFS('지출 Expenses'!$D$3:$D$1002,'지출 Expenses'!$A$3:$A$1002,">="&$A17,'지출 Expenses'!$A$3:$A$1002,"<="&$B17) | E17: =$C17-$D17 | F17: =IF(OR('설정 Settings'!$C$39="NO",$A17<'설정 Settings'!$C$41),"-","A") | G17: =IF($E17<=0,0,'설정 Settings'!$C$44*MIN($E17,$R$6)+MAX(0,$E17-$R$6)) | H17: =IF($F17="A",MAX(0,$R$4-$G17),0) | I17: =$H17+$E17 | J17: =$H17+$E17-MAX(0,$E17)*$R$7 | K17: =$E17-MAX(0,$E17)*$R$7 | L17: =IFERROR(($R$4-'설정 Settings'!$C$44*$E17+(1-$R$7)*$E17)/(1-$R$7),"")
A18: 46390 | B18: =$A18+6 | C18: =SUMIFS('작업 Jobs'!$H$3:$H$1002,'작업 Jobs'!$C$3:$C$1002,">="&$A18,'작업 Jobs'!$C$3:$C$1002,"<="&$B18) | D18: =SUMIFS('지출 Expenses'!$D$3:$D$1002,'지출 Expenses'!$A$3:$A$1002,">="&$A18,'지출 Expenses'!$A$3:$A$1002,"<="&$B18) | E18: =$C18-$D18 | F18: =IF(OR('설정 Settings'!$C$39="NO",$A18<'설정 Settings'!$C$41),"-","A") | G18: =IF($E18<=0,0,'설정 Settings'!$C$44*MIN($E18,$R$6)+MAX(0,$E18-$R$6)) | H18: =IF($F18="A",MAX(0,$R$4-$G18),0) | I18: =$H18+$E18 | J18: =$H18+$E18-MAX(0,$E18)*$R$7 | K18: =$E18-MAX(0,$E18)*$R$7 | L18: =IFERROR(($R$4-'설정 Settings'!$C$44*$E18+(1-$R$7)*$E18)/(1-$R$7),"")
A19: 46397 | B19: =$A19+6 | C19: =SUMIFS('작업 Jobs'!$H$3:$H$1002,'작업 Jobs'!$C$3:$C$1002,">="&$A19,'작업 Jobs'!$C$3:$C$1002,"<="&$B19) | D19: =SUMIFS('지출 Expenses'!$D$3:$D$1002,'지출 Expenses'!$A$3:$A$1002,">="&$A19,'지출 Expenses'!$A$3:$A$1002,"<="&$B19) | E19: =$C19-$D19 | F19: =IF(OR('설정 Settings'!$C$39="NO",$A19<'설정 Settings'!$C$41),"-","A") | G19: =IF($E19<=0,0,'설정 Settings'!$C$44*MIN($E19,$R$6)+MAX(0,$E19-$R$6)) | H19: =IF($F19="A",MAX(0,$R$4-$G19),0) | I19: =$H19+$E19 | J19: =$H19+$E19-MAX(0,$E19)*$R$7 | K19: =$E19-MAX(0,$E19)*$R$7 | L19: =IFERROR(($R$4-'설정 Settings'!$C$44*$E19+(1-$R$7)*$E19)/(1-$R$7),"")
A20: 46404 | B20: =$A20+6 | C20: =SUMIFS('작업 Jobs'!$H$3:$H$1002,'작업 Jobs'!$C$3:$C$1002,">="&$A20,'작업 Jobs'!$C$3:$C$1002,"<="&$B20) | D20: =SUMIFS('지출 Expenses'!$D$3:$D$1002,'지출 Expenses'!$A$3:$A$1002,">="&$A20,'지출 Expenses'!$A$3:$A$1002,"<="&$B20) | E20: =$C20-$D20 | F20: =IF(OR('설정 Settings'!$C$39="NO",$A20<'설정 Settings'!$C$41),"-","A") | G20: =IF($E20<=0,0,'설정 Settings'!$C$44*MIN($E20,$R$6)+MAX(0,$E20-$R$6)) | H20: =IF($F20="A",MAX(0,$R$4-$G20),0) | I20: =$H20+$E20 | J20: =$H20+$E20-MAX(0,$E20)*$R$7 | K20: =$E20-MAX(0,$E20)*$R$7 | L20: =IFERROR(($R$4-'설정 Settings'!$C$44*$E20+(1-$R$7)*$E20)/(1-$R$7),"")
A21: 46411 | B21: =$A21+6 | C21: =SUMIFS('작업 Jobs'!$H$3:$H$1002,'작업 Jobs'!$C$3:$C$1002,">="&$A21,'작업 Jobs'!$C$3:$C$1002,"<="&$B21) | D21: =SUMIFS('지출 Expenses'!$D$3:$D$1002,'지출 Expenses'!$A$3:$A$1002,">="&$A21,'지출 Expenses'!$A$3:$A$1002,"<="&$B21) | E21: =$C21-$D21 | F21: =IF(OR('설정 Settings'!$C$39="NO",$A21<'설정 Settings'!$C$41),"-","A") | G21: =IF($E21<=0,0,'설정 Settings'!$C$44*MIN($E21,$R$6)+MAX(0,$E21-$R$6)) | H21: =IF($F21="A",MAX(0,$R$4-$G21),0) | I21: =$H21+$E21 | J21: =$H21+$E21-MAX(0,$E21)*$R$7 | K21: =$E21-MAX(0,$E21)*$R$7 | L21: =IFERROR(($R$4-'설정 Settings'!$C$44*$E21+(1-$R$7)*$E21)/(1-$R$7),"")
A22: 46418 | B22: =$A22+6 | C22: =SUMIFS('작업 Jobs'!$H$3:$H$1002,'작업 Jobs'!$C$3:$C$1002,">="&$A22,'작업 Jobs'!$C$3:$C$1002,"<="&$B22) | D22: =SUMIFS('지출 Expenses'!$D$3:$D$1002,'지출 Expenses'!$A$3:$A$1002,">="&$A22,'지출 Expenses'!$A$3:$A$1002,"<="&$B22) | E22: =$C22-$D22 | F22: =IF(OR('설정 Settings'!$C$39="NO",$A22<'설정 Settings'!$C$41),"-","A") | G22: =IF($E22<=0,0,'설정 Settings'!$C$44*MIN($E22,$R$6)+MAX(0,$E22-$R$6)) | H22: =IF($F22="A",MAX(0,$R$4-$G22),0) | I22: =$H22+$E22 | J22: =$H22+$E22-MAX(0,$E22)*$R$7 | K22: =$E22-MAX(0,$E22)*$R$7 | L22: =IFERROR(($R$4-'설정 Settings'!$C$44*$E22+(1-$R$7)*$E22)/(1-$R$7),"")
A23: 46425 | B23: =$A23+6 | C23: =SUMIFS('작업 Jobs'!$H$3:$H$1002,'작업 Jobs'!$C$3:$C$1002,">="&$A23,'작업 Jobs'!$C$3:$C$1002,"<="&$B23) | D23: =SUMIFS('지출 Expenses'!$D$3:$D$1002,'지출 Expenses'!$A$3:$A$1002,">="&$A23,'지출 Expenses'!$A$3:$A$1002,"<="&$B23) | E23: =$C23-$D23 | F23: =IF(OR('설정 Settings'!$C$39="NO",$A23<'설정 Settings'!$C$41),"-","A") | G23: =IF($E23<=0,0,'설정 Settings'!$C$44*MIN($E23,$R$6)+MAX(0,$E23-$R$6)) | H23: =IF($F23="A",MAX(0,$R$4-$G23),0) | I23: =$H23+$E23 | J23: =$H23+$E23-MAX(0,$E23)*$R$7 | K23: =$E23-MAX(0,$E23)*$R$7 | L23: =IFERROR(($R$4-'설정 Settings'!$C$44*$E23+(1-$R$7)*$E23)/(1-$R$7),"")
A24: 46432 | B24: =$A24+6 | C24: =SUMIFS('작업 Jobs'!$H$3:$H$1002,'작업 Jobs'!$C$3:$C$1002,">="&$A24,'작업 Jobs'!$C$3:$C$1002,"<="&$B24) | D24: =SUMIFS('지출 Expenses'!$D$3:$D$1002,'지출 Expenses'!$A$3:$A$1002,">="&$A24,'지출 Expenses'!$A$3:$A$1002,"<="&$B24) | E24: =$C24-$D24 | F24: =IF(OR('설정 Settings'!$C$39="NO",$A24<'설정 Settings'!$C$41),"-","A") | G24: =IF($E24<=0,0,'설정 Settings'!$C$44*MIN($E24,$R$6)+MAX(0,$E24-$R$6)) | H24: =IF($F24="A",MAX(0,$R$4-$G24),0) | I24: =$H24+$E24 | J24: =$H24+$E24-MAX(0,$E24)*$R$7 | K24: =$E24-MAX(0,$E24)*$R$7 | L24: =IFERROR(($R$4-'설정 Settings'!$C$44*$E24+(1-$R$7)*$E24)/(1-$R$7),"")
A25: 46439 | B25: =$A25+6 | C25: =SUMIFS('작업 Jobs'!$H$3:$H$1002,'작업 Jobs'!$C$3:$C$1002,">="&$A25,'작업 Jobs'!$C$3:$C$1002,"<="&$B25) | D25: =SUMIFS('지출 Expenses'!$D$3:$D$1002,'지출 Expenses'!$A$3:$A$1002,">="&$A25,'지출 Expenses'!$A$3:$A$1002,"<="&$B25) | E25: =$C25-$D25 | F25: =IF(OR('설정 Settings'!$C$39="NO",$A25<'설정 Settings'!$C$41),"-","A") | G25: =IF($E25<=0,0,'설정 Settings'!$C$44*MIN($E25,$R$6)+MAX(0,$E25-$R$6)) | H25: =IF($F25="A",MAX(0,$R$4-$G25),0) | I25: =$H25+$E25 | J25: =$H25+$E25-MAX(0,$E25)*$R$7 | K25: =$E25-MAX(0,$E25)*$R$7 | L25: =IFERROR(($R$4-'설정 Settings'!$C$44*$E25+(1-$R$7)*$E25)/(1-$R$7),"")
A26: 46446 | B26: =$A26+6 | C26: =SUMIFS('작업 Jobs'!$H$3:$H$1002,'작업 Jobs'!$C$3:$C$1002,">="&$A26,'작업 Jobs'!$C$3:$C$1002,"<="&$B26) | D26: =SUMIFS('지출 Expenses'!$D$3:$D$1002,'지출 Expenses'!$A$3:$A$1002,">="&$A26,'지출 Expenses'!$A$3:$A$1002,"<="&$B26) | E26: =$C26-$D26 | F26: =IF(OR('설정 Settings'!$C$39="NO",$A26<'설정 Settings'!$C$41),"-","A") | G26: =IF($E26<=0,0,'설정 Settings'!$C$44*MIN($E26,$R$6)+MAX(0,$E26-$R$6)) | H26: =IF($F26="A",MAX(0,$R$4-$G26),0) | I26: =$H26+$E26 | J26: =$H26+$E26-MAX(0,$E26)*$R$7 | K26: =$E26-MAX(0,$E26)*$R$7 | L26: =IFERROR(($R$4-'설정 Settings'!$C$44*$E26+(1-$R$7)*$E26)/(1-$R$7),"")
A27: 46453 | B27: =$A27+6 | C27: =SUMIFS('작업 Jobs'!$H$3:$H$1002,'작업 Jobs'!$C$3:$C$1002,">="&$A27,'작업 Jobs'!$C$3:$C$1002,"<="&$B27) | D27: =SUMIFS('지출 Expenses'!$D$3:$D$1002,'지출 Expenses'!$A$3:$A$1002,">="&$A27,'지출 Expenses'!$A$3:$A$1002,"<="&$B27) | E27: =$C27-$D27 | F27: =IF(OR('설정 Settings'!$C$39="NO",$A27<'설정 Settings'!$C$41),"-","A") | G27: =IF($E27<=0,0,'설정 Settings'!$C$44*MIN($E27,$R$6)+MAX(0,$E27-$R$6)) | H27: =IF($F27="A",MAX(0,$R$4-$G27),0) | I27: =$H27+$E27 | J27: =$H27+$E27-MAX(0,$E27)*$R$7 | K27: =$E27-MAX(0,$E27)*$R$7 | L27: =IFERROR(($R$4-'설정 Settings'!$C$44*$E27+(1-$R$7)*$E27)/(1-$R$7),"")
A28: 46460 | B28: =$A28+6 | C28: =SUMIFS('작업 Jobs'!$H$3:$H$1002,'작업 Jobs'!$C$3:$C$1002,">="&$A28,'작업 Jobs'!$C$3:$C$1002,"<="&$B28) | D28: =SUMIFS('지출 Expenses'!$D$3:$D$1002,'지출 Expenses'!$A$3:$A$1002,">="&$A28,'지출 Expenses'!$A$3:$A$1002,"<="&$B28) | E28: =$C28-$D28 | F28: =IF(OR('설정 Settings'!$C$39="NO",$A28<'설정 Settings'!$C$41),"-","A") | G28: =IF($E28<=0,0,'설정 Settings'!$C$44*MIN($E28,$R$6)+MAX(0,$E28-$R$6)) | H28: =IF($F28="A",MAX(0,$R$4-$G28),0) | I28: =$H28+$E28 | J28: =$H28+$E28-MAX(0,$E28)*$R$7 | K28: =$E28-MAX(0,$E28)*$R$7 | L28: =IFERROR(($R$4-'설정 Settings'!$C$44*$E28+(1-$R$7)*$E28)/(1-$R$7),"")
... A34: 46502 | B34: =$A34+6 | C34: =SUMIFS('작업 Jobs'!$H$3:$H$1002,'작업 Jobs'!$C$3:$C$1002,">="&$A34,'작업 Jobs'!$C$3:$C$1002,"<="&$B34) | D34: =SUMIFS('지출 Expenses'!$D$3:$D$1002,'지출 Expenses'!$A$3:$A$1002,">="&$A34,'지출 Expenses'!$A$3:$A$1002,"<="&$B34) | E34: =$C34-$D34 | F34: =IF(OR('설정 Settings'!$C$39="NO",$A34<'설정 Settings'!$C$41),"-","A") | G34: =IF($E34<=0,0,'설정 Settings'!$C$44*MIN($E34,$R$6)+MAX(0,$E34-$R$6)) | H34: =IF($F34="A",MAX(0,$R$4-$G34),0) | I34: =$H34+$E34 | J34: =$H34+$E34-MAX(0,$E34)*$R$7 | K34: =$E34-MAX(0,$E34)*$R$7 | L34: =IFERROR(($R$4-'설정 Settings'!$C$44*$E34+(1-$R$7)*$E34)/(1-$R$7),"")

Sheet 세금 Tax
A1: 세금 Tax — GST/HST 분기 점검, CPP 적립, T2125 분류 (세무 자문 아님)
A2: 매출은 작업 시트의 완료일 기준, 지출은 지출 시트 기준입니다. 입금 시트와의 차이는 미수금·입금 시기 때문입니다. 소규모 사업자 기준 $30,000: 4분기 합계 테스트 + 단일 분기 테스트 (ETA s.148, F7). 경고선: 4분기 $25,000, 단일 분기 $20,000 (memo §10 item 15).
A4: 분기 Quarter | B4: 시작 | C4: 끝 | D4: 총매출 Gross (Jobs) | E4: 과세매출 (테스트) Taxable (test) | F4: 4분기 합계 Rolling 4Q | G4: 단일 분기 경고 Single-quarter | H4: 4분기 경고 Rolling flag | I4: 입금 합계 Payments | J4: 차이 Diff | K4: 지출 Expenses | L4: 순이익 Net | M4: CPP 적립 11.9% Set aside
